Workbook

Sheet Sheet1
C1: APC公式の測定データを使用
C3: 1lbf = | D3: 0.45359 | E3: kgf = | F3: =D3*1000 -> 453.59 | G3: gf
C4: = | D4: 4.44822 | E4: Ｎ
D5: =D4/D3 -> 9.8066977
C7: 1in = | D7: 25.4 | E7: mm = | F7: =D7/1000 -> 0.0254 | G7: m
C9: 1in-lbf = | D9: =D4*F7 -> 0.11298479 | E9: Nm | I9: 9.81
C12: 12x6E | E12: 12x6 Sport | M12: 5x3 | U12: 5x3E
C13: lbf | D13: N | E13: lbf | F13: N | H13: rpm | J13: g | K13: N | N13: lbf | O13: N | P13: mN | Q13: in-lbf | R13: Nm | U13: lbf | V13: N | W13: mN | X13: in-lbf | Y13: Nm | Z13: mNmm
B14: 1000 | C14: 0.054 | D14: =C14*$D$4 -> 0.24020388 | E14: 0.067 | F14: =E14*$D$4 -> 0.29803074 | H14: 9651 | I14: =H14/60 -> 160.85 | J14: 75 | K14: =J14*$I$9 -> 735.75 | L14: 1000 | M14: =L14/60 -> 16.666667 | N14: 0.003 | O14: =N14*$D$4 -> 0.01334466 | P14: =O14*1000 -> 13.34466 | Q14: 0.001 | R14: =Q14*$D$9 -> 0.00011298479 | U14: 0.002 | V14: =U14*$D$4 -> 0.00889644 | W14: =V14*1000 -> 8.89644 | X14: 0.001 | Y14: =X14*$D$9 -> 0.00011298479 | Z14: =Y14*10^6 -> 112.98479
B15: 2000 | C15: 0.216 | D15: =C15*$D$4 -> 0.96081552 | E15: 0.269 | F15: =E15*$D$4 -> 1.1965712 | H15: 12823 | I15: =H15/60 -> 213.71667 | J15: 133 | K15: =J15*$I$9 -> 1304.73 | L15: 2000 | M15: =L15/60 -> 33.333333 | N15: 0.01 | O15: =N15*$D$4 -> 0.0444822 | P15: =O15*1000 -> 44.4822 | Q15: 0.004 | R15: =Q15*$D$9 -> 0.00045193915 | U15: 0.009 | V15: =U15*$D$4 -> 0.04003398 | W15: =V15*1000 -> 40.03398 | X15: 0.003 | Y15: =X15*$D$9 -> 0.00033895436 | Z15: =Y15*10^6 -> 338.95436
B16: 3000 | C16: 0.478 | D16: =C16*$D$4 -> 2.1262492 | E16: 0.608 | F16: =E16*$D$4 -> 2.7045178 | H16: 15026 | I16: =H16/60 -> 250.43333 | J16: 185 | K16: =J16*$I$9 -> 1814.85 | L16: 3000 | M16: =L16/60 -> 50 | N16: 0.023 | O16: =N16*$D$4 -> 0.10230906 | P16: =O16*1000 -> 102.30906 | Q16: 0.008 | R16: =Q16*$D$9 -> 0.0009038783 | U16: 0.02 | V16: =U16*$D$4 -> 0.0889644 | W16: =V16*1000 -> 88.9644 | X16: 0.007 | Y16: =X16*$D$9 -> 0.00079089352 | Z16: =Y16*10^6 -> 790.89352
B17: 4000 | C17: 0.867 | D17: =C17*$D$4 -> 3.8566067 | E17: 1.081 | F17: =E17*$D$4 -> 4.8085258 | H17: 16800 | I17: =H17/60 -> 280 | J17: 233 | K17: =J17*$I$9 -> 2285.73 | L17: 4000 | M17: =L17/60 -> 66.666667 | N17: 0.041 | O17: =N17*$D$4 -> 0.18237702 | P17: =O17*1000 -> 182.37702 | Q17: 0.015 | R17: =Q17*$D$9 -> 0.0016947718 | U17: 0.036 | V17: =U17*$D$4 -> 0.16013592 | W17: =V17*1000 -> 160.13592 | X17: 0.013 | Y17: =X17*$D$9 -> 0.0014688022 | Z17: =Y17*10^6 -> 1468.8022
B18: 5000 | C18: 1.356 | D18: =C18*$D$4 -> 6.0317863 | E18: 1.688 | F18: =E18*$D$4 -> 7.5085954 | H18: 18283 | I18: =H18/60 -> 304.71667 | J18: 273 | K18: =J18*$I$9 -> 2678.13 | L18: 5000 | M18: =L18/60 -> 83.333333 | N18: 0.063 | O18: =N18*$D$4 -> 0.28023786 | P18: =O18*1000 -> 280.23786 | Q18: 0.023 | R18: =Q18*$D$9 -> 0.0025986501 | U18: 0.057 | V18: =U18*$D$4 -> 0.25354854 | W18: =V18*1000 -> 253.54854 | X18: 0.02 | Y18: =X18*$D$9 -> 0.0022596958 | Z18: =Y18*10^6 -> 2259.6958
B19: 6000 | C19: 1.955 | D19: =C19*$D$4 -> 8.6962701 | E19: 2.442 | F19: =E19*$D$4 -> 10.862553 | H19: 19749 | I19: =H19/60 -> 329.15 | J19: 318 | K19: =J19*$I$9 -> 3119.58 | L19: 6000 | M19: =L19/60 -> 100 | N19: 0.091 | O19: =N19*$D$4 -> 0.40478802 | P19: =O19*1000 -> 404.78802 | Q19: 0.034 | R19: =Q19*$D$9 -> 0.0038414828 | U19: 0.082 | V19: =U19*$D$4 -> 0.36475404 | W19: =V19*1000 -> 364.75404 | X19: 0.029 | Y19: =X19*$D$9 -> 0.0032765589 | Z19: =Y19*10^6 -> 3276.5589
B20: 7000 | C20: 2.668 | D20: =C20*$D$4 -> 11.867851 | E20: 3.335 | F20: =E20*$D$4 -> 14.834814 | H20: 20974 | I20: =H20/60 -> 349.56667 | J20: 353 | K20: =J20*$I$9 -> 3462.93 | L20: 7000 | M20: =L20/60 -> 116.66667 | N20: 0.124 | O20: =N20*$D$4 -> 0.55157928 | P20: =O20*1000 -> 551.57928 | Q20: 0.046 | R20: =Q20*$D$9 -> 0.0051973002 | U20: 0.112 | V20: =U20*$D$4 -> 0.49820064 | W20: =V20*1000 -> 498.20064 | X20: 0.039 | Y20: =X20*$D$9 -> 0.0044064067 | Z20: =Y20*10^6 -> 4406.4067
B21: 8000 | E21: 4.424 | F21: =E21*$D$4 -> 19.678925 | H21: 22029 | I21: =H21/60 -> 367.15 | J21: 390 | K21: =J21*$I$9 -> 3825.9 | L21: 8000 | M21: =L21/60 -> 133.33333 | N21: 0.162 | O21: =N21*$D$4 -> 0.72061164 | P21: =O21*1000 -> 720.61164 | Q21: 0.06 | R21: =Q21*$D$9 -> 0.0067790873 | U21: 0.146 | V21: =U21*$D$4 -> 0.64944012 | W21: =V21*1000 -> 649.44012 | X21: 0.051 | Y21: =X21*$D$9 -> 0.0057622242 | Z21: =Y21*10^6 -> 5762.2242
B22: 9000 | E22: 5.653 | F22: =E22*$D$4 -> 25.145788 | H22: 22894 | I22: =H22/60 -> 381.56667 | J22: 425 | K22: =J22*$I$9 -> 4169.25 | L22: 9000 | M22: =L22/60 -> 150 | N22: 0.206 | O22: =N22*$D$4 -> 0.91633332 | P22: =O22*1000 -> 916.33332 | Q22: 0.076 | R22: =Q22*$D$9 -> 0.0085868439 | U22: 0.185 | V22: =U22*$D$4 -> 0.8229207 | W22: =V22*1000 -> 822.9207 | X22: 0.065 | Y22: =X22*$D$9 -> 0.0073440112 | Z22: =Y22*10^6 -> 7344.0112
B23: 10000 | E23: 7.053 | F23: =E23*$D$4 -> 31.373296 | L23: 10000 | M23: =L23/60 -> 166.66667 | N23: 0.254 | O23: =N23*$D$4 -> 1.1298479 | P23: =O23*1000 -> 1129.8479 | Q23: 0.094 | R23: =Q23*$D$9 -> 0.01062057 | U23: 0.228 | V23: =U23*$D$4 -> 1.0141942 | W23: =V23*1000 -> 1014.1942 | X23: 0.08 | Y23: =X23*$D$9 -> 0.009038783 | Z23: =Y23*10^6 -> 9038.783
L24: 11000 | M24: =L24/60 -> 183.33333 | N24: 0.308 | O24: =N24*$D$4 -> 1.3700518 | P24: =O24*1000 -> 1370.0518 | Q24: 0.115 | R24: =Q24*$D$9 -> 0.012993251 | U24: 0.276 | V24: =U24*$D$4 -> 1.2277087 | W24: =V24*1000 -> 1227.7087 | X24: 0.097 | Y24: =X24*$D$9 -> 0.010959524 | Z24: =Y24*10^6 -> 10959.524
C25: 1.656 | D25: =C25*$D$4 -> 7.3662523 | L25: 12000 | M25: =L25/60 -> 200 | N25: 0.366 | O25: =N25*$D$4 -> 1.6280485 | P25: =O25*1000 -> 1628.0485 | Q25: 0.137 | R25: =Q25*$D$9 -> 0.015478916 | U25: 0.329 | V25: =U25*$D$4 -> 1.4634644 | W25: =V25*1000 -> 1463.4644 | X25: 0.116 | Y25: =X25*$D$9 -> 0.013106235 | Z25: =Y25*10^6 -> 13106.235
L26: 13000 | M26: =L26/60 -> 216.66667 | N26: 0.43 | O26: =N26*$D$4 -> 1.9127346 | P26: =O26*1000 -> 1912.7346 | Q26: 0.161 | R26: =Q26*$D$9 -> 0.018190551 | U26: 0.387 | V26: =U26*$D$4 -> 1.7214611 | W26: =V26*1000 -> 1721.4611 | X26: 0.137 | Y26: =X26*$D$9 -> 0.015478916 | Z26: =Y26*10^6 -> 15478.916
L27: 14000 | M27: =L27/60 -> 233.33333 | N27: 0.5 | O27: =N27*$D$4 -> 2.22411 | P27: =O27*1000 -> 2224.11 | Q27: 0.187 | R27: =Q27*$D$9 -> 0.021128155 | U27: 0.449 | V27: =U27*$D$4 -> 1.9972508 | W27: =V27*1000 -> 1997.2508 | X27: 0.159 | Y27: =X27*$D$9 -> 0.017964581 | Z27: =Y27*10^6 -> 17964.581
L28: 15000 | M28: =L28/60 -> 250 | N28: 0.575 | O28: =N28*$D$4 -> 2.5577265 | P28: =O28*1000 -> 2557.7265 | Q28: 0.215 | R28: =Q28*$D$9 -> 0.024291729 | U28: 0.516 | V28: =U28*$D$4 -> 2.2952815 | W28: =V28*1000 -> 2295.2815 | X28: 0.183 | Y28: =X28*$D$9 -> 0.020676216 | Z28: =Y28*10^6 -> 20676.216
L29: 16000 | M29: =L29/60 -> 266.66667 | N29: 0.655 | O29: =N29*$D$4 -> 2.9135841 | P29: =O29*1000 -> 2913.5841 | Q29: 0.245 | R29: =Q29*$D$9 -> 0.027681273 | U29: 0.588 | V29: =U29*$D$4 -> 2.6155534 | W29: =V29*1000 -> 2615.5534 | X29: 0.209 | Y29: =X29*$D$9 -> 0.023613821 | Z29: =Y29*10^6 -> 23613.821
L30: 17000 | M30: =L30/60 -> 283.33333 | N30: 0.74 | O30: =N30*$D$4 -> 3.2916828 | P30: =O30*1000 -> 3291.6828 | Q30: 0.278 | R30: =Q30*$D$9 -> 0.031409771 | U30: 0.665 | V30: =U30*$D$4 -> 2.9580663 | W30: =V30*1000 -> 2958.0663 | X30: 0.236 | Y30: =X30*$D$9 -> 0.02666441 | Z30: =Y30*10^6 -> 26664.41
C31: 12x6E | E31: 12x6 Sport | L31: 18000 | M31: =L31/60 -> 300 | N31: 0.831 | O31: =N31*$D$4 -> 3.6964708 | P31: =O31*1000 -> 3696.4708 | Q31: 0.311 | R31: =Q31*$D$9 -> 0.035138269 | U31: 0.747 | V31: =U31*$D$4 -> 3.3228203 | W31: =V31*1000 -> 3322.8203 | X31: 0.266 | Y31: =X31*$D$9 -> 0.030053954 | Z31: =Y31*10^6 -> 30053.954
C32: in-lbf | D32: Nm | E32: in-lbf | F32: Nm | L32: 19000 | M32: =L32/60 -> 316.66667 | N32: 0.927 | O32: =N32*$D$4 -> 4.1234999 | P32: =O32*1000 -> 4123.4999 | Q32: 0.344 | R32: =Q32*$D$9 -> 0.038866767 | U32: 0.834 | V32: =U32*$D$4 -> 3.7098155 | W32: =V32*1000 -> 3709.8155 | X32: 0.297 | Y32: =X32*$D$9 -> 0.033556482 | Z32: =Y32*10^6 -> 33556.482
B33: 1000 | C33: 0.057 | D33: =C33*$D$9 -> 0.0064401329 | E33: 0.077 | F33: =E33*$D$9 -> 0.0086998287 | L33: 20000 | M33: =L33/60 -> 333.33333 | N33: 1.028 | O33: =N33*$D$4 -> 4.5727702 | P33: =O33*1000 -> 4572.7702 | Q33: 0.38 | R33: =Q33*$D$9 -> 0.042934219 | U33: 0.925 | V33: =U33*$D$4 -> 4.1146035 | W33: =V33*1000 -> 4114.6035 | X33: 0.331 | Y33: =X33*$D$9 -> 0.037397965 | Z33: =Y33*10^6 -> 37397.965
B34: 2000 | C34: 0.229 | D34: =C34*$D$9 -> 0.025873516 | E34: 0.308 | F34: =E34*$D$9 -> 0.034799315
B35: 3000 | C35: 0.516 | D35: =C35*$D$9 -> 0.058300151 | E35: 0.695 | F35: =E35*$D$9 -> 0.078524428
B36: 4000 | C36: 0.919 | D36: =C36*$D$9 -> 0.10383302 | E36: 1.216 | F36: =E36*$D$9 -> 0.1373895 | L36: 16.666667 | M36: =0.0374*L36^2-0.1385*L36 -> 8.0805556 | N36: =0.3428*L36^2-2.6737*L36 -> 50.660556 | O36: =0.0374*L36^2 -> 10.388889 | P36: =0.3428*L36^2 -> 95.222222
B37: 5000 | C37: 1.406 | D37: =C37*$D$9 -> 0.15885661 | E37: 1.859 | F37: =E37*$D$9 -> 0.21003872 | L37: 33.333333 | M37: =0.0374*L37^2-0.1385*L37 -> 36.938889 | N37: =0.3428*L37^2-2.6737*L37 -> 291.76556 | O37: =0.0374*L37^2 -> 41.555556 | P37: =0.3428*L37^2 -> 380.88889
B38: 6000 | C38: 1.983 | D38: =C38*$D$9 -> 0.22404883 | E38: 2.688 | F38: =E38*$D$9 -> 0.30370311 | L38: 50 | M38: =0.0374*L38^2-0.1385*L38 -> 86.575 | N38: =0.3428*L38^2-2.6737*L38 -> 723.315 | O38: =0.0374*L38^2 -> 93.5 | P38: =0.3428*L38^2 -> 857
B39: 7000 | C39: 2.656 | D39: =C39*$D$9 -> 0.3000876 | E39: 3.779 | F39: =E39*$D$9 -> 0.42696951 | I39: 1200 | J39: 3850 | L39: 66.666667 | M39: =0.0374*L39^2-0.1385*L39 -> 156.98889 | N39: =0.3428*L39^2-2.6737*L39 -> 1345.3089 | O39: =0.0374*L39^2 -> 166.22222 | P39: =0.3428*L39^2 -> 1523.5556
B40: 8000 | E40: 5.086 | F40: =E40*$D$9 -> 0.57464063 | I40: 1250 | J40: 5580 | L40: 83.333333 | M40: =0.0374*L40^2-0.1385*L40 -> 248.18056 | N40: =0.3428*L40^2-2.6737*L40 -> 2157.7472 | O40: =0.0374*L40^2 -> 259.72222 | P40: =0.3428*L40^2 -> 2380.5556
B41: 9000 | E41: 6.622 | F41: =E41*$D$9 -> 0.74818527 | I41: 1300 | J41: 7330 | L41: 100 | M41: =0.0374*L41^2-0.1385*L41 -> 360.15 | N41: =0.3428*L41^2-2.6737*L41 -> 3160.63 | O41: =0.0374*L41^2 -> 374 | P41: =0.3428*L41^2 -> 3428
B42: 10000 | E42: 8.412 | F42: =E42*$D$9 -> 0.95042804 | I42: 1350 | J42: 9090 | L42: 116.66667 | M42: =0.0374*L42^2-0.1385*L42 -> 492.89722 | N42: =0.3428*L42^2-2.6737*L42 -> 4353.9572 | O42: =0.0374*L42^2 -> 509.05556 | P42: =0.3428*L42^2 -> 4665.8889
I43: 1400 | J43: 10700 | L43: 133.33333 | M43: =0.0374*L43^2-0.1385*L43 -> 646.42222 | N43: =0.3428*L43^2-2.6737*L43 -> 5737.7289 | O43: =0.0374*L43^2 -> 664.88889 | P43: =0.3428*L43^2 -> 6094.2222
I44: 1450 | J44: 12150 | L44: 150 | M44: =0.0374*L44^2-0.1385*L44 -> 820.725 | N44: =0.3428*L44^2-2.6737*L44 -> 7311.945 | O44: =0.0374*L44^2 -> 841.5 | P44: =0.3428*L44^2 -> 7713
I45: 1500 | J45: 13550 | L45: 166.66667 | M45: =0.0374*L45^2-0.1385*L45 -> 1015.8056 | N45: =0.3428*L45^2-2.6737*L45 -> 9076.6056 | O45: =0.0374*L45^2 -> 1038.8889 | P45: =0.3428*L45^2 -> 9522.2222
...

Sheet A20-22LEVO
C2: メーカー | D2: Hacker | F2: 電流[A] | G2: 有効トルク[Nm] | H2: 回転数[rpm] | I2: 出力[W] | J2: 効率[%] | K2: mNm
C3: 品番 | D3: A20-22LEVO | I3: =H3*PI()/30*G3 -> 0 | J3: =I3/($D$32*F3)*100 -> #DIV/0! | K3: =G3*1000 -> 0
C4: URL | D4: http://www.powers-international.com/aero/hacker/a20evo.htm | F4: =D16 -> 0.75 | G4: =F4*$D$29-$D$30 -> 0 | H4: =D33 -> 6190.8 | I4: =H4*PI()/30*G4 -> 0 | J4: =I4/($D$32*F4)*100 -> 0 | K4: =G4*1000 -> 0
F5: =F4+$D$16 -> 1.5 | G5: =F5*$D$29-$D$30 -> 0.0077510524 | H5: =H4-$D$27*(G5-G4) -> 6129.123 | I5: =H5*PI()/30*G5 -> 4.9749375 | J5: =I5/($D$32*F5)*100 -> 49.501866 | K5: =G5*1000 -> 7.7510524
B6: ハード | C6: 本体直径 | D6: 28 | E6: mm | F6: =F5+$D$16 -> 2.25 | G6: =F6*$D$29-$D$30 -> 0.015502105 | H6: =H5-$D$27*(G6-G5) -> 6067.446 | I6: =H6*PI()/30*G6 -> 9.84975 | J6: =I6/($D$32*F6)*100 -> 65.338308 | K6: =G6*1000 -> 15.502105
C7: 本体長さ | D7: 34 | E7: mm | F7: =F6+$D$16 -> 3 | G7: =F7*$D$29-$D$30 -> 0.023253157 | H7: =H6-$D$27*(G7-G6) -> 6005.769 | I7: =H7*PI()/30*G7 -> 14.624438 | J7: =I7/($D$32*F7)*100 -> 72.758396 | K7: =G7*1000 -> 23.253157
C8: シャフト径 | D8: 3 | E8: mm | F8: =F7+$D$16 -> 3.75 | G8: =F8*$D$29-$D$30 -> 0.03100421 | H8: =H7-$D$27*(G8-G7) -> 5944.092 | I8: =H8*PI()/30*G8 -> 19.299 | J8: =I8/($D$32*F8)*100 -> 76.81194 | K8: =G8*1000 -> 31.00421
C9: シャフト長 | D9: 12 | E9: mm | F9: =F8+$D$16 -> 4.5 | G9: =F9*$D$29-$D$30 -> 0.038755262 | H9: =H8-$D$27*(G9-G8) -> 5882.415 | I9: =H9*PI()/30*G9 -> 23.873438 | J9: =I9/($D$32*F9)*100 -> 79.182214 | K9: =G9*1000 -> 38.755262
C10: 重量 | D10: 55 | E10: g | F10: =F9+$D$16 -> 5.25 | G10: =F10*$D$29-$D$30 -> 0.046506315 | H10: =H9-$D$27*(G10-G9) -> 5820.738 | I10: =H10*PI()/30*G10 -> 28.34775 | J10: =I10/($D$32*F10)*100 -> 80.590618 | K10: =G10*1000 -> 46.506315
F11: =F10+$D$16 -> 6 | G11: =F11*$D$29-$D$30 -> 0.054257367 | H11: =H10-$D$27*(G11-G10) -> 5759.061 | I11: =H11*PI()/30*G11 -> 32.721938 | J11: =I11/($D$32*F11)*100 -> 81.397854 | K11: =G11*1000 -> 54.257367
B12: カタログスペック | C12: KV値 | D12: 924 | E12: rpm/V | F12: =F11+$D$16 -> 6.75 | G12: =F12*$D$29-$D$30 -> 0.062008419 | H12: =H11-$D$27*(G12-G11) -> 5697.384 | I12: =H12*PI()/30*G12 -> 36.996 | J12: =I12/($D$32*F12)*100 -> 81.804312 | K12: =G12*1000 -> 62.008419
C13: 最大出力Pmax | D13: 200 | E13: W(15sec) | F13: =F12+$D$16 -> 7.5 | G13: =F13*$D$29-$D$30 -> 0.069759472 | H13: =H12-$D$27*(G13-G12) -> 5635.707 | I13: =H13*PI()/30*G13 -> 41.169938 | J13: =I13/($D$32*F13)*100 -> 81.930224 | K13: =G13*1000 -> 69.759472
C14: 最大電流Ipeak | D14: 19 | E14: A(※con.15) | F14: =F13+$D$16 -> 8.25 | G14: =F14*$D$29-$D$30 -> 0.077510524 | H14: =H13-$D$27*(G14-G13) -> 5574.03 | I14: =H14*PI()/30*G14 -> 45.24375 | J14: =I14/($D$32*F14)*100 -> 81.852103 | K14: =G14*1000 -> 77.510524
C15: 最高効率ηmax | D15: 85 | E15: %(※A20-22Lの値) | F15: =F14+$D$16 -> 9 | G15: =F15*$D$29-$D$30 -> 0.085261577 | H15: =H14-$D$27*(G15-G14) -> 5512.353 | I15: =H15*PI()/30*G15 -> 49.217438 | J15: =I15/($D$32*F15)*100 -> 81.620958 | K15: =G15*1000 -> 85.261577
C16: 無負荷時電流I0 | D16: 0.75 | E16: A(8.4V時) | F16: =F15+$D$16 -> 9.75 | G16: =F16*$D$29-$D$30 -> 0.093012629 | H16: =H15-$D$27*(G16-G15) -> 5450.676 | I16: =H16*PI()/30*G16 -> 53.091 | J16: =I16/($D$32*F16)*100 -> 81.272101 | K16: =G16*1000 -> 93.012629
C17: 内部抵抗Rm | D17: 0.089 | E17: ohm | F17: =F16+$D$16 -> 10.5 | G17: =F17*$D$29-$D$30 -> 0.10076368 | H17: =H16-$D$27*(G17-G16) -> 5388.999 | I17: =H17*PI()/30*G17 -> 56.864438 | J17: =I17/($D$32*F17)*100 -> 80.830757 | K17: =G17*1000 -> 100.76368
C18: 極数 | D18: 14 | F18: =F17+$D$16 -> 11.25 | G18: =F18*$D$29-$D$30 -> 0.10851473 | H18: =H17-$D$27*(G18-G17) -> 5327.322 | I18: =H18*PI()/30*G18 -> 60.53775 | J18: =I18/($D$32*F18)*100 -> 80.315423 | K18: =G18*1000 -> 108.51473
C19: ターン数 | D19: 22 | F19: =F18+$D$16 -> 12 | G19: =F19*$D$29-$D$30 -> 0.11626579 | H19: =H18-$D$27*(G19-G18) -> 5265.645 | I19: =H19*PI()/30*G19 -> 64.110938 | J19: =I19/($D$32*F19)*100 -> 79.739972 | K19: =G19*1000 -> 116.26579
C20: 最高回転数Npeak | D20: 20000 | E20: rpm(※A20-22Lの値) | F20: =F19+$D$16 -> 12.75 | G20: =F20*$D$29-$D$30 -> 0.12401684 | H20: =H19-$D$27*(G20-G19) -> 5203.968 | I20: =H20*PI()/30*G20 -> 67.584 | J20: =I20/($D$32*F20)*100 -> 79.115013 | K20: =G20*1000 -> 124.01684
C21: ESC タイミング | D21: 20-25 | E21: deg | F21: =F20+$D$16 -> 13.5 | G21: =F21*$D$29-$D$30 -> 0.13176789 | H21: =H20-$D$27*(G21-G20) -> 5142.291 | I21: =H21*PI()/30*G21 -> 70.956938 | J21: =I21/($D$32*F21)*100 -> 78.448798 | K21: =G21*1000 -> 131.76789
C22: ESC 周波数 | D22: 8～16 | E22: kHz | F22: =F21+$D$16 -> 14.25 | G22: =F22*$D$29-$D$30 -> 0.13951894 | H22: =H21-$D$27*(G22-G21) -> 5080.614 | I22: =H22*PI()/30*G22 -> 74.22975 | J22: =I22/($D$32*F22)*100 -> 77.74784 | K22: =G22*1000 -> 139.51894
F23: =F22+$D$16 -> 15 | G23: =F23*$D$29-$D$30 -> 0.14727 | H23: =H22-$D$27*(G23-G22) -> 5018.937 | I23: =H23*PI()/30*G23 -> 77.402438 | J23: =I23/($D$32*F23)*100 -> 77.017351 | K23: =G23*1000 -> 147.27
C24: I0測定時の電圧 | D24: 8.4 | E24: V | F24: =F23+$D$16 -> 15.75 | G24: =F24*$D$29-$D$30 -> 0.15502105 | H24: =H23-$D$27*(G24-G23) -> 4957.26 | I24: =H24*PI()/30*G24 -> 80.475 | J24: =I24/($D$32*F24)*100 -> 76.261549 | K24: =G24*1000 -> 155.02105
C25: 無負荷時回転数？ | D25: =D12*D24 -> 7761.6 | E25: rpm | F25: =F24+$D$16 -> 16.5 | G25: =F25*$D$29-$D$30 -> 0.1627721 | H25: =H24-$D$27*(G25-G24) -> 4895.583 | I25: =H25*PI()/30*G25 -> 83.447438 | J25: =I25/($D$32*F25)*100 -> 75.483887 | K25: =G25*1000 -> 162.7721
D26: =D25*(PI()/30) -> 812.79285 | E26: rad/sec | F26: =F25+$D$16 -> 17.25 | G26: =F26*$D$29-$D$30 -> 0.17052315 | H26: =H25-$D$27*(G26-G25) -> 4833.906 | I26: =H26*PI()/30*G26 -> 86.31975 | J26: =I26/($D$32*F26)*100 -> 74.687216 | K26: =G26*1000 -> 170.52315
A27: maxon | C27: 回転数/トルク勾配 | D27: =(PI()/30)*((D17*D25^2)/(D24^2)) -> 7957.242 | E27: rpm/Nm | F27: =F26+$D$16 -> 18 | G27: =F27*$D$29-$D$30 -> 0.17827421 | H27: =H26-$D$27*(G27-G26) -> 4772.229 | I27: =H27*PI()/30*G27 -> 89.091938 | J27: =I27/($D$32*F27)*100 -> 73.873912 | K27: =G27*1000 -> 178.27421
C28: 逆起電力定数Ke | D28: =D24/D26 -> 0.010334737 | E28: Vsec/rad | F28: =F27+$D$16 -> 18.75 | G28: =F28*$D$29-$D$30 -> 0.18602526 | H28: =H27-$D$27*(G28-G27) -> 4710.552 | I28: =H28*PI()/30*G28 -> 91.764 | J28: =I28/($D$32*F28)*100 -> 73.04597 | K28: =G28*1000 -> 186.02526
C29: トルク定数Kt | D29: =D28 -> 0.010334737 | E29: Nm/A | F29: 19 | G29: =F29*$D$29-$D$30 -> 0.18860894 | H29: =H28-$D$27*(G29-G28) -> 4689.993 | I29: =H29*PI()/30*G29 -> 92.632438 | J29: =I29/($D$32*F29)*100 -> 72.767037 | K29: =G29*1000 -> 188.60894
C30: モータ内損失トルクTd | D30: =D29*D16 -> 0.0077510524 | E30: Nm
C32: 駆動電圧V | D32: =Graph!M2 -> 6.7 | E32: V
C33: 理論最高回転数Nmax | D33: =D12*D32 -> 6190.8 | E33: rpm
C34: Nmax≦Npeak？ | D34: =D33/D20 -> 0.30954
A35: maxon | C35: 起動電流IA | D35: =D32/D17 -> 75.280899 | E35: A
C37: Rm/Kt^2 | D37: =D17/(D29^2) -> 833.28044
C40: 最高効率時電流Iηmax | D40: =SQRT(D16*D32/D17) -> 7.5140318 | E40: A
C41: nmax | D41: =((D40-D16)/D40)^2*100 -> 81.033617 | E41: %
C42: I | D42: =D40 -> 7.5140318 | E42: A
C43: Pout | D43: =(D42-D16)*(D32-D42*D17) -> 40.795575 | E43: W

Sheet A20-30MEVO
C2: メーカー | D2: Hacker | F2: 電流[A] | G2: 有効トルク[Nm] | H2: 回転数[rpm] | I2: 出力[W] | J2: 効率[%] | K2: mNm
C3: 品番 | D3: A20-30MEVO | I3: =H3*PI()/30*G3 -> 0 | J3: =I3/($D$32*F3)*100 -> #DIV/0! | K3: =G3*1000 -> 0
C4: URL | D4: http://www.powers-international.com/aero/hacker/a20evo.htm | F4: =D16 -> 0.6 | G4: =F4*$D$29-$D$30 -> 0 | H4: =D33 -> 6566 | I4: =H4*PI()/30*G4 -> 0 | J4: =I4/($D$32*F4)*100 -> 0 | K4: =G4*1000 -> 0
F5: =F4+$D$16 -> 1.2 | G5: =F5*$D$29-$D$30 -> 0.0058465081 | H5: =H4-$D$27*(G5-G4) -> 6463.688 | I5: =H5*PI()/30*G5 -> 3.95736 | J5: =I5/($D$32*F5)*100 -> 49.220896 | K5: =G5*1000 -> 5.8465081
B6: ハード | C6: 本体直径 | D6: 28 | E6: mm | F6: =F5+$D$16 -> 1.8 | G6: =F6*$D$29-$D$30 -> 0.011693016 | H6: =H5-$D$27*(G6-G5) -> 6361.376 | I6: =H6*PI()/30*G6 -> 7.78944 | J6: =I6/($D$32*F6)*100 -> 64.589055 | K6: =G6*1000 -> 11.693016
C7: 本体長さ | D7: 30 | E7: mm | F7: =F6+$D$16 -> 2.4 | G7: =F7*$D$29-$D$30 -> 0.017539524 | H7: =H6-$D$27*(G7-G6) -> 6259.064 | I7: =H7*PI()/30*G7 -> 11.49624 | J7: =I7/($D$32*F7)*100 -> 71.49403 | K7: =G7*1000 -> 17.539524
C8: シャフト径 | D8: 3 | E8: mm | F8: =F7+$D$16 -> 3 | G8: =F8*$D$29-$D$30 -> 0.023386032 | H8: =H7-$D$27*(G8-G7) -> 6156.752 | I8: =H8*PI()/30*G8 -> 15.07776 | J8: =I8/($D$32*F8)*100 -> 75.013731 | K8: =G8*1000 -> 23.386032
C9: シャフト長 | D9: 12 | E9: mm | F9: =F8+$D$16 -> 3.6 | G9: =F9*$D$29-$D$30 -> 0.029232541 | H9: =H8-$D$27*(G9-G8) -> 6054.44 | I9: =H9*PI()/30*G9 -> 18.534 | J9: =I9/($D$32*F9)*100 -> 76.840796 | K9: =G9*1000 -> 29.232541
C10: 重量 | D10: 42 | E10: g | F10: =F9+$D$16 -> 4.2 | G10: =F10*$D$29-$D$30 -> 0.035079049 | H10: =H9-$D$27*(G10-G9) -> 5952.128 | I10: =H10*PI()/30*G10 -> 21.86496 | J10: =I10/($D$32*F10)*100 -> 77.70064 | K10: =G10*1000 -> 35.079049
F11: =F10+$D$16 -> 4.8 | G11: =F11*$D$29-$D$30 -> 0.040925557 | H11: =H10-$D$27*(G11-G10) -> 5849.816 | I11: =H11*PI()/30*G11 -> 25.07064 | J11: =I11/($D$32*F11)*100 -> 77.95597 | K11: =G11*1000 -> 40.925557
B12: カタログスペック | C12: KV値 | D12: 980 | E12: rpm/V | F12: =F11+$D$16 -> 5.4 | G12: =F12*$D$29-$D$30 -> 0.046772065 | H12: =H11-$D$27*(G12-G11) -> 5747.504 | I12: =H12*PI()/30*G12 -> 28.15104 | J12: =I12/($D$32*F12)*100 -> 77.808292 | K12: =G12*1000 -> 46.772065
C13: 最大出力Pmax | D13: 150 | E13: W(15sec) | F13: =F12+$D$16 -> 6 | G13: =F13*$D$29-$D$30 -> 0.052618573 | H13: =H12-$D$27*(G13-G12) -> 5645.192 | I13: =H13*PI()/30*G13 -> 31.10616 | J13: =I13/($D$32*F13)*100 -> 77.378507 | K13: =G13*1000 -> 52.618573
C14: 最大電流Ipeak | D14: 15 | E14: A(※con.12) | F14: =F13+$D$16 -> 6.6 | G14: =F14*$D$29-$D$30 -> 0.058465081 | H14: =H13-$D$27*(G14-G13) -> 5542.88 | I14: =H14*PI()/30*G14 -> 33.936 | J14: =I14/($D$32*F14)*100 -> 76.743555 | K14: =G14*1000 -> 58.465081
C15: 最高効率ηmax | E15: %(※) | F15: =F14+$D$16 -> 7.2 | G15: =F15*$D$29-$D$30 -> 0.064311589 | H15: =H14-$D$27*(G15-G14) -> 5440.568 | I15: =H15*PI()/30*G15 -> 36.64056 | J15: =I15/($D$32*F15)*100 -> 75.954726 | K15: =G15*1000 -> 64.311589
C16: 無負荷時電流I0 | D16: 0.6 | E16: A(8.4V時) | F16: =F15+$D$16 -> 7.8 | G16: =F16*$D$29-$D$30 -> 0.070158097 | H16: =H15-$D$27*(G16-G15) -> 5338.256 | I16: =H16*PI()/30*G16 -> 39.21984 | J16: =I16/($D$32*F16)*100 -> 75.047532 | K16: =G16*1000 -> 70.158097
C17: 内部抵抗Rm | D17: 0.174 | E17: ohm | F17: =F16+$D$16 -> 8.4 | G17: =F17*$D$29-$D$30 -> 0.076004605 | H17: =H16-$D$27*(G17-G16) -> 5235.944 | I17: =H17*PI()/30*G17 -> 41.67384 | J17: =I17/($D$32*F17)*100 -> 74.047335 | K17: =G17*1000 -> 76.004605
C18: 極数 | D18: 14 | F18: =F17+$D$16 -> 9 | G18: =F18*$D$29-$D$30 -> 0.081851114 | H18: =H17-$D$27*(G18-G17) -> 5133.632 | I18: =H18*PI()/30*G18 -> 44.00256 | J18: =I18/($D$32*F18)*100 -> 72.972736 | K18: =G18*1000 -> 81.851114
C19: ターン数 | D19: 30 | F19: =F18+$D$16 -> 9.6 | G19: =F19*$D$29-$D$30 -> 0.087697622 | H19: =H18-$D$27*(G19-G18) -> 5031.32 | I19: =H19*PI()/30*G19 -> 46.206 | J19: =I19/($D$32*F19)*100 -> 71.837687 | K19: =G19*1000 -> 87.697622
C20: 最高回転数Npeak | E20: rpm(※) | F20: =F19+$D$16 -> 10.2 | G20: =F20*$D$29-$D$30 -> 0.09354413 | H20: =H19-$D$27*(G20-G19) -> 4929.008 | I20: =H20*PI()/30*G20 -> 48.28416 | J20: =I20/($D$32*F20)*100 -> 70.652853 | K20: =G20*1000 -> 93.54413
C21: ESC タイミング | D21: 20-25 | E21: deg | F21: =F20+$D$16 -> 10.8 | G21: =F21*$D$29-$D$30 -> 0.099390638 | H21: =H20-$D$27*(G21-G20) -> 4826.696 | I21: =H21*PI()/30*G21 -> 50.23704 | J21: =I21/($D$32*F21)*100 -> 69.426534 | K21: =G21*1000 -> 99.390638
C22: ESC 周波数 | D22: 8～16 | E22: kHz | F22: =F21+$D$16 -> 11.4 | G22: =F22*$D$29-$D$30 -> 0.10523715 | H22: =H21-$D$27*(G22-G21) -> 4724.384 | I22: =H22*PI()/30*G22 -> 52.06464 | J22: =I22/($D$32*F22)*100 -> 68.165279 | K22: =G22*1000 -> 105.23715
F23: =F22+$D$16 -> 12 | G23: =F23*$D$29-$D$30 -> 0.11108365 | H23: =H22-$D$27*(G23-G22) -> 4622.072 | I23: =H23*PI()/30*G23 -> 53.76696 | J23: =I23/($D$32*F23)*100 -> 66.874328 | K23: =G23*1000 -> 111.08365
C24: I0測定時の電圧 | D24: 8.4 | E24: V | F24: =F23+$D$16 -> 12.6 | G24: =F24*$D$29-$D$30 -> 0.11693016 | H24: =H23-$D$27*(G24-G23) -> 4519.76 | I24: =H24*PI()/30*G24 -> 55.344 | J24: =I24/($D$32*F24)*100 -> 65.557925 | K24: =G24*1000 -> 116.93016
C25: 無負荷時回転数？ | D25: =D12*D24 -> 8232 | E25: rpm | F25: =F24+$D$16 -> 13.2 | G25: =F25*$D$29-$D$30 -> 0.12277667 | H25: =H24-$D$27*(G25-G24) -> 4417.448 | I25: =H25*PI()/30*G25 -> 56.79576 | J25: =I25/($D$32*F25)*100 -> 64.219539 | K25: =G25*1000 -> 122.77667
D26: =D25*(PI()/30) -> 862.05302 | E26: rad/sec | F26: =F25+$D$16 -> 13.8 | G26: =F26*$D$29-$D$30 -> 0.12862318 | H26: =H25-$D$27*(G26-G25) -> 4315.136 | I26: =H26*PI()/30*G26 -> 58.12224 | J26: =I26/($D$32*F26)*100 -> 62.862038 | K26: =G26*1000 -> 128.62318
A27: maxon | C27: 回転数/トルク勾配 | D27: =(PI()/30)*((D17*D25^2)/(D24^2)) -> 17499.676 | E27: rpm/Nm | F27: =F26+$D$16 -> 14.4 | G27: =F27*$D$29-$D$30 -> 0.13446969 | H27: =H26-$D$27*(G27-G26) -> 4212.824 | I27: =H27*PI()/30*G27 -> 59.32344 | J27: =I27/($D$32*F27)*100 -> 61.487811 | K27: =G27*1000 -> 134.46969
C28: 逆起電力定数Ke | D28: =D24/D26 -> 0.0097441802 | E28: Vsec/rad | F28: 15 | G28: =F28*$D$29-$D$30 -> 0.14031619 | H28: =H27-$D$27*(G28-G27) -> 4110.512 | I28: =H28*PI()/30*G28 -> 60.39936 | J28: =I28/($D$32*F28)*100 -> 60.098866 | K28: =G28*1000 -> 140.31619
C29: トルク定数Kt | D29: =D28 -> 0.0097441802 | E29: Nm/A
C30: モータ内損失トルクTd | D30: =D29*D16 -> 0.0058465081 | E30: Nm
C32: 駆動電圧V | D32: =Graph!M2 -> 6.7 | E32: V
C33: 理論最高回転数Nmax | D33: =D12*D32 -> 6566 | E33: rpm
C34: Nmax≦Npeak？ | D34: =D33/D20 -> #DIV/0!
A35: maxon | C35: 起動電流IA | D35: =D32/D17 -> 38.505747 | E35: A
C37: Rm/Kt^2 | D37: =D17/(D29^2) -> 1832.5618
C40: 最高効率時電流Iηmax | D40: =SQRT(D16*D32/D17) -> 4.8066047 | E40: A
C41: nmax | D41: =((D40-D16)/D40)^2*100 -> 76.592561 | E41: %
C42: I | D42: =D40 -> 4.8066047 | E42: A
C43: Pout | D43: =(D42-D16)*(D32-D42*D17) -> 24.666061 | E43: W

Sheet ZS2213-22
C2: メーカー | D2: Hyperion | F2: 電流[A] | G2: 有効トルク[Nm] | H2: 回転数[rpm] | I2: 出力[W] | J2: 効率[%] | K2: mNm
C3: 品番 | D3: ZS2213-22 | I3: =H3*PI()/30*G3 -> 0 | J3: =I3/($D$32*F3)*100 -> #DIV/0! | K3: =G3*1000 -> 0
C4: URL | F4: =D16 -> 0.46 | G4: =F4*$D$29-$D$30 -> 0 | H4: =D33 -> 5775.4 | I4: =H4*PI()/30*G4 -> 0 | J4: =I4/($D$32*F4)*100 -> 0 | K4: =G4*1000 -> 0
F5: =F4+$D$16 -> 0.92 | G5: =F5*$D$29-$D$30 -> 0.0050959123 | H5: =H4-$D$27*(G5-G4) -> 5729.4037 | I5: =H5*PI()/30*G5 -> 3.0574544 | J5: =I5/($D$32*F5)*100 -> 49.601791 | K5: =G5*1000 -> 5.0959123
B6: ハード | C6: 本体直径 | D6: 28 | E6: mm | F6: =F5+$D$16 -> 1.38 | G6: =F6*$D$29-$D$30 -> 0.010191825 | H6: =H5-$D$27*(G6-G5) -> 5683.4074 | I6: =H6*PI()/30*G6 -> 6.0658176 | J6: =I6/($D$32*F6)*100 -> 65.604776 | K6: =G6*1000 -> 10.191825
C7: 本体長さ | D7: 30.5 | E7: mm | F7: =F6+$D$16 -> 1.84 | G7: =F7*$D$29-$D$30 -> 0.015287737 | H7: =H6-$D$27*(G7-G6) -> 5637.411 | I7: =H7*PI()/30*G7 -> 9.0250896 | J7: =I7/($D$32*F7)*100 -> 73.20806 | K7: =G7*1000 -> 15.287737
C8: シャフト径 | D8: 3 | E8: mm | F8: =F7+$D$16 -> 2.3 | G8: =F8*$D$29-$D$30 -> 0.020383649 | H8: =H7-$D$27*(G8-G7) -> 5591.4147 | I8: =H8*PI()/30*G8 -> 11.93527 | J8: =I8/($D$32*F8)*100 -> 77.451463 | K8: =G8*1000 -> 20.383649
C9: シャフト長 | D9: 11 | E9: mm | F9: =F8+$D$16 -> 2.76 | G9: =F9*$D$29-$D$30 -> 0.025479562 | H9: =H8-$D$27*(G9-G8) -> 5545.4184 | I9: =H9*PI()/30*G9 -> 14.79636 | J9: =I9/($D$32*F9)*100 -> 80.014925 | K9: =G9*1000 -> 25.479562
C10: 重量 | D10: 59.7 | E10: g | F10: =F9+$D$16 -> 3.22 | G10: =F10*$D$29-$D$30 -> 0.030575474 | H10: =H9-$D$27*(G10-G9) -> 5499.4221 | I10: =H10*PI()/30*G10 -> 17.608358 | J10: =I10/($D$32*F10)*100 -> 81.618422 | K10: =G10*1000 -> 30.575474
F11: =F10+$D$16 -> 3.68 | G11: =F11*$D$29-$D$30 -> 0.035671386 | H11: =H10-$D$27*(G11-G10) -> 5453.4258 | I11: =H11*PI()/30*G11 -> 20.371266 | J11: =I11/($D$32*F11)*100 -> 82.62194 | K11: =G11*1000 -> 35.671386
B12: カタログスペック | C12: KV値 | D12: 862 | E12: rpm/V | F12: =F11+$D$16 -> 4.14 | G12: =F12*$D$29-$D$30 -> 0.040767299 | H12: =H11-$D$27*(G12-G11) -> 5407.4294 | I12: =H12*PI()/30*G12 -> 23.085082 | J12: =I12/($D$32*F12)*100 -> 83.225473 | K12: =G12*1000 -> 40.767299
C13: 最大出力Pmax | D13: 240 | E13: W | F13: =F12+$D$16 -> 4.6 | G13: =F13*$D$29-$D$30 -> 0.045863211 | H13: =H12-$D$27*(G13-G12) -> 5361.4331 | I13: =H13*PI()/30*G13 -> 25.749806 | J13: =I13/($D$32*F13)*100 -> 83.549015 | K13: =G13*1000 -> 45.863211
C14: 最大電流Ipeak | D14: 21 | E14: A(10sec) | F14: =F13+$D$16 -> 5.06 | G14: =F14*$D$29-$D$30 -> 0.050959123 | H14: =H13-$D$27*(G14-G13) -> 5315.4368 | I14: =H14*PI()/30*G14 -> 28.36544 | J14: =I14/($D$32*F14)*100 -> 83.668928 | K14: =G14*1000 -> 50.959123
C15: 最高効率ηmax | E15: %(※A20-22Lの値) | F15: =F14+$D$16 -> 5.52 | G15: =F15*$D$29-$D$30 -> 0.056055036 | H15: =H14-$D$27*(G15-G14) -> 5269.4405 | I15: =H15*PI()/30*G15 -> 30.931982 | J15: =I15/($D$32*F15)*100 -> 83.636119 | K15: =G15*1000 -> 56.055036
C16: 無負荷時電流I0 | D16: 0.46 | E16: A(10V時) | F16: =F15+$D$16 -> 5.98 | G16: =F16*$D$29-$D$30 -> 0.061150948 | H16: =H15-$D$27*(G16-G15) -> 5223.4442 | I16: =H16*PI()/30*G16 -> 33.449434 | J16: =I16/($D$32*F16)*100 -> 83.485832 | K16: =G16*1000 -> 61.150948
C17: 内部抵抗Rm | D17: 0.116 | E17: ohm | F17: =F16+$D$16 -> 6.44 | G17: =F17*$D$29-$D$30 -> 0.06624686 | H17: =H16-$D$27*(G17-G16) -> 5177.4478 | I17: =H17*PI()/30*G17 -> 35.917794 | J17: =I17/($D$32*F17)*100 -> 83.243241 | K17: =G17*1000 -> 66.24686
C18: 極数 | F18: =F17+$D$16 -> 6.9 | G18: =F18*$D$29-$D$30 -> 0.071342773 | H18: =H17-$D$27*(G18-G17) -> 5131.4515 | I18: =H18*PI()/30*G18 -> 38.337062 | J18: =I18/($D$32*F18)*100 -> 82.926806 | K18: =G18*1000 -> 71.342773
C19: ターン数 | D19: 22 | F19: =F18+$D$16 -> 7.36 | G19: =F19*$D$29-$D$30 -> 0.076438685 | H19: =H18-$D$27*(G19-G18) -> 5085.4552 | I19: =H19*PI()/30*G19 -> 40.70724 | J19: =I19/($D$32*F19)*100 -> 82.550373 | K19: =G19*1000 -> 76.438685
C20: 最高回転数Npeak | E20: rpm | F20: =F19+$D$16 -> 7.82 | G20: =F20*$D$29-$D$30 -> 0.081534597 | H20: =H19-$D$27*(G20-G19) -> 5039.4589 | I20: =H20*PI()/30*G20 -> 43.028326 | J20: =I20/($D$32*F20)*100 -> 82.12453 | K20: =G20*1000 -> 81.534597
C21: ESC タイミング | E21: deg | F21: =F20+$D$16 -> 8.28 | G21: =F21*$D$29-$D$30 -> 0.08663051 | H21: =H20-$D$27*(G21-G20) -> 4993.4626 | I21: =H21*PI()/30*G21 -> 45.300322 | J21: =I21/($D$32*F21)*100 -> 81.657512 | K21: =G21*1000 -> 86.63051
C22: ESC 周波数 | E22: kHz | F22: =F21+$D$16 -> 8.74 | G22: =F22*$D$29-$D$30 -> 0.091726422 | H22: =H21-$D$27*(G22-G21) -> 4947.4662 | I22: =H22*PI()/30*G22 -> 47.523226 | J22: =I22/($D$32*F22)*100 -> 81.155821 | K22: =G22*1000 -> 91.726422
F23: =F22+$D$16 -> 9.2 | G23: =F23*$D$29-$D$30 -> 0.096822334 | H23: =H22-$D$27*(G23-G22) -> 4901.4699 | I23: =H23*PI()/30*G23 -> 49.697038 | J23: =I23/($D$32*F23)*100 -> 80.624657 | K23: =G23*1000 -> 96.822334
C24: I0測定時の電圧 | D24: 10 | E24: V | F24: =F23+$D$16 -> 9.66 | G24: =F24*$D$29-$D$30 -> 0.10191825 | H24: =H23-$D$27*(G24-G23) -> 4855.4736 | I24: =H24*PI()/30*G24 -> 51.82176 | J24: =I24/($D$32*F24)*100 -> 80.06823 | K24: =G24*1000 -> 101.91825
C25: 無負荷時回転数？ | D25: =D12*D24 -> 8620 | E25: rpm | F25: =F24+$D$16 -> 10.12 | G25: =F25*$D$29-$D$30 -> 0.10701416 | H25: =H24-$D$27*(G25-G24) -> 4809.4773 | I25: =H25*PI()/30*G25 -> 53.89739 | J25: =I25/($D$32*F25)*100 -> 79.489986 | K25: =G25*1000 -> 107.01416
D26: =D25*(PI()/30) -> 902.68429 | E26: rad/sec | F26: =F25+$D$16 -> 10.58 | G26: =F26*$D$29-$D$30 -> 0.11211007 | H26: =H25-$D$27*(G26-G25) -> 4763.481 | I26: =H26*PI()/30*G26 -> 55.92393 | J26: =I26/($D$32*F26)*100 -> 78.892771 | K26: =G26*1000 -> 112.11007
A27: maxon | C27: 回転数/トルク勾配 | D27: =(PI()/30)*((D17*D25^2)/(D24^2)) -> 9026.1207 | E27: rpm/Nm | F27: =F26+$D$16 -> 11.04 | G27: =F27*$D$29-$D$30 -> 0.11720598 | H27: =H26-$D$27*(G27-G26) -> 4717.4846 | I27: =H27*PI()/30*G27 -> 57.901378 | J27: =I27/($D$32*F27)*100 -> 78.278955 | K27: =G27*1000 -> 117.20598
C28: 逆起電力定数Ke | D28: =D24/D26 -> 0.01107807 | E28: Vsec/rad | F28: =F27+$D$16 -> 11.5 | G28: =F28*$D$29-$D$30 -> 0.1223019 | H28: =H27-$D$27*(G28-G27) -> 4671.4883 | I28: =H28*PI()/30*G28 -> 59.829734 | J28: =I28/($D$32*F28)*100 -> 77.650531 | K28: =G28*1000 -> 122.3019
C29: トルク定数Kt | D29: =D28 -> 0.01107807 | E29: Nm/A | F29: =F28+$D$16 -> 11.96 | G29: =F29*$D$29-$D$30 -> 0.12739781 | H29: =H28-$D$27*(G29-G28) -> 4625.492 | I29: =H29*PI()/30*G29 -> 61.709 | J29: =I29/($D$32*F29)*100 -> 77.009185 | K29: =G29*1000 -> 127.39781
C30: モータ内損失トルクTd | D30: =D29*D16 -> 0.0050959123 | E30: Nm | F30: =F29+$D$16 -> 12.42 | G30: =F30*$D$29-$D$30 -> 0.13249372 | H30: =H29-$D$27*(G30-G29) -> 4579.4957 | I30: =H30*PI()/30*G30 -> 63.539174 | J30: =I30/($D$32*F30)*100 -> 76.356352 | K30: =G30*1000 -> 132.49372
F31: =F30+$D$16 -> 12.88 | G31: =F31*$D$29-$D$30 -> 0.13758963 | H31: =H30-$D$27*(G31-G30) -> 4533.4994 | I31: =H31*PI()/30*G31 -> 65.320258 | J31: =I31/($D$32*F31)*100 -> 75.693262 | K31: =G31*1000 -> 137.58963
C32: 駆動電圧V | D32: =Graph!M2 -> 6.7 | E32: V | F32: =F31+$D$16 -> 13.34 | G32: =F32*$D$29-$D$30 -> 0.14268555 | H32: =H31-$D$27*(G32-G31) -> 4487.503 | I32: =H32*PI()/30*G32 -> 67.05225 | J32: =I32/($D$32*F32)*100 -> 75.020978 | K32: =G32*1000 -> 142.68555
C33: 理論最高回転数Nmax | D33: =D12*D32 -> 5775.4 | E33: rpm | F33: =F32+$D$16 -> 13.8 | G33: =F33*$D$29-$D$30 -> 0.14778146 | H33: =H32-$D$27*(G33-G32) -> 4441.5067 | I33: =H33*PI()/30*G33 -> 68.73515 | J33: =I33/($D$32*F33)*100 -> 74.340418 | K33: =G33*1000 -> 147.78146
C34: Nmax≦Npeak？ | D34: =D33/D20 -> #DIV/0! | F34: =F33+$D$16 -> 14.26 | G34: =F34*$D$29-$D$30 -> 0.15287737 | H34: =H33-$D$27*(G34-G33) -> 4395.5104 | I34: =H34*PI()/30*G34 -> 70.36896 | J34: =I34/($D$32*F34)*100 -> 73.652383 | K34: =G34*1000 -> 152.87737
A35: maxon | C35: 起動電流IA | D35: =D32/D17 -> 57.758621 | E35: A | F35: =F34+$D$16 -> 14.72 | G35: =F35*$D$29-$D$30 -> 0.15797328 | H35: =H34-$D$27*(G35-G34) -> 4349.5141 | I35: =H35*PI()/30*G35 -> 71.953678 | J35: =I35/($D$32*F35)*100 -> 72.957575 | K35: =G35*1000 -> 157.97328
F36: =F35+$D$16 -> 15.18 | G36: =F36*$D$29-$D$30 -> 0.16306919 | H36: =H35-$D$27*(G36-G35) -> 4303.5178 | I36: =H36*PI()/30*G36 -> 73.489306 | J36: =I36/($D$32*F36)*100 -> 72.256608 | K36: =G36*1000 -> 163.06919
C37: Rm/Kt^2 | D37: =D17/(D29^2) -> 945.21315 | F37: =F36+$D$16 -> 15.64 | G37: =F37*$D$29-$D$30 -> 0.16816511 | H37: =H36-$D$27*(G37-G36) -> 4257.5214 | I37: =H37*PI()/30*G37 -> 74.975842 | J37: =I37/($D$32*F37)*100 -> 71.550026 | K37: =G37*1000 -> 168.16511
F38: =F37+$D$16 -> 16.1 | G38: =F38*$D$29-$D$30 -> 0.17326102 | H38: =H37-$D$27*(G38-G37) -> 4211.5251 | I38: =H38*PI()/30*G38 -> 76.413286 | J38: =I38/($D$32*F38)*100 -> 70.838311 | K38: =G38*1000 -> 173.26102
F39: =F38+$D$16 -> 16.56 | G39: =F39*$D$29-$D$30 -> 0.17835693 | H39: =H38-$D$27*(G39-G38) -> 4165.5288 | I39: =H39*PI()/30*G39 -> 77.80164 | J39: =I39/($D$32*F39)*100 -> 70.121891 | K39: =G39*1000 -> 178.35693
C40: 最高効率時電流Iηmax | D40: =SQRT(D16*D32/D17) -> 5.1545092 | E40: A | F40: =F39+$D$16 -> 17.02 | G40: =F40*$D$29-$D$30 -> 0.18345284 | H40: =H39-$D$27*(G40-G39) -> 4119.5325 | I40: =H40*PI()/30*G40 -> 79.140902 | J40: =I40/($D$32*F40)*100 -> 69.401146 | K40: =G40*1000 -> 183.45284
C41: nmax | D41: =((D40-D16)/D40)^2*100 -> 82.947968 | E41: % | F41: =F40+$D$16 -> 17.48 | G41: =F41*$D$29-$D$30 -> 0.18854876 | H41: =H40-$D$27*(G41-G40) -> 4073.5362 | I41: =H41*PI()/30*G41 -> 80.431074 | J41: =I41/($D$32*F41)*100 -> 68.676418 | K41: =G41*1000 -> 188.54876
...

Sheet ZS2209-30
C2: メーカー | D2: Hyperion | F2: 電流[A] | G2: 有効トルク[Nm] | H2: 回転数[rpm] | I2: 出力[W] | J2: 効率[%] | K2: mNm
C3: 品番 | D3: ZS2209-30 | I3: =H3*PI()/30*G3 -> 0 | J3: =I3/($D$32*F3)*100 -> #DIV/0! | K3: =G3*1000 -> 0
C4: URL | D4: http://aircraft-japan.com/prod_datasheets/hp/zs22/zs22.htm | F4: =D16 -> 0.45 | G4: =F4*$D$29-$D$30 -> 0 | H4: =D33 -> 6365 | I4: =H4*PI()/30*G4 -> 0 | J4: =I4/($D$32*F4)*100 -> 0 | K4: =G4*1000 -> 0
F5: =F4+$D$16 -> 0.9 | G5: =F5*$D$29-$D$30 -> 0.004523351 | H5: =H4-$D$27*(G5-G4) -> 6296.1725 | I5: =H5*PI()/30*G5 -> 2.9823975 | J5: =I5/($D$32*F5)*100 -> 49.459328 | K5: =G5*1000 -> 4.523351
B6: ハード | C6: 本体直径 | D6: 28 | E6: mm | F6: =F5+$D$16 -> 1.35 | G6: =F6*$D$29-$D$30 -> 0.009046702 | H6: =H5-$D$27*(G6-G5) -> 6227.345 | I6: =H6*PI()/30*G6 -> 5.89959 | J6: =I6/($D$32*F6)*100 -> 65.224876 | K6: =G6*1000 -> 9.046702
C7: 本体長さ | D7: 26.6 | E7: mm | F7: =F6+$D$16 -> 1.8 | G7: =F7*$D$29-$D$30 -> 0.013570053 | H7: =H6-$D$27*(G7-G6) -> 6158.5175 | I7: =H7*PI()/30*G7 -> 8.7515775 | J7: =I7/($D$32*F7)*100 -> 72.566978 | K7: =G7*1000 -> 13.570053
C8: シャフト径 | D8: 3 | E8: mm | F8: =F7+$D$16 -> 2.25 | G8: =F8*$D$29-$D$30 -> 0.018093404 | H8: =H7-$D$27*(G8-G7) -> 6089.69 | I8: =H8*PI()/30*G8 -> 11.53836 | J8: =I8/($D$32*F8)*100 -> 76.539701 | K8: =G8*1000 -> 18.093404
C9: シャフト長 | D9: 11 | E9: mm | F9: =F8+$D$16 -> 2.7 | G9: =F9*$D$29-$D$30 -> 0.022616755 | H9: =H8-$D$27*(G9-G8) -> 6020.8625 | I9: =H9*PI()/30*G9 -> 14.259937 | J9: =I9/($D$32*F9)*100 -> 78.827736 | K9: =G9*1000 -> 22.616755
C10: 重量 | D10: 45.4 | E10: g | F10: =F9+$D$16 -> 3.15 | G10: =F10*$D$29-$D$30 -> 0.027140106 | H10: =H9-$D$27*(G10-G9) -> 5952.035 | I10: =H10*PI()/30*G10 -> 16.91631 | J10: =I10/($D$32*F10)*100 -> 80.153092 | K10: =G10*1000 -> 27.140106
F11: =F10+$D$16 -> 3.6 | G11: =F11*$D$29-$D$30 -> 0.031663457 | H11: =H10-$D$27*(G11-G10) -> 5883.2075 | I11: =H11*PI()/30*G11 -> 19.507477 | J11: =I11/($D$32*F11)*100 -> 80.876772 | K11: =G11*1000 -> 31.663457
B12: カタログスペック | C12: KV値 | D12: 950 | E12: rpm/V | F12: =F11+$D$16 -> 4.05 | G12: =F12*$D$29-$D$30 -> 0.036186808 | H12: =H11-$D$27*(G12-G11) -> 5814.38 | I12: =H12*PI()/30*G12 -> 22.03344 | J12: =I12/($D$32*F12)*100 -> 81.199337 | K12: =G12*1000 -> 36.186808
C13: 最大出力Pmax | D13: 190 | E13: W | F13: =F12+$D$16 -> 4.5 | G13: =F13*$D$29-$D$30 -> 0.040710159 | H13: =H12-$D$27*(G13-G12) -> 5745.5525 | I13: =H13*PI()/30*G13 -> 24.494197 | J13: =I13/($D$32*F13)*100 -> 81.241119 | K13: =G13*1000 -> 40.710159
C14: 最大電流Ipeak | D14: 17 | E14: A(10sec) | F14: =F13+$D$16 -> 4.95 | G14: =F14*$D$29-$D$30 -> 0.04523351 | H14: =H13-$D$27*(G14-G13) -> 5676.725 | I14: =H14*PI()/30*G14 -> 26.88975 | J14: =I14/($D$32*F14)*100 -> 81.078697 | K14: =G14*1000 -> 45.23351
C15: 最高効率ηmax | E15: %(※) | F15: =F14+$D$16 -> 5.4 | G15: =F15*$D$29-$D$30 -> 0.049756861 | H15: =H14-$D$27*(G15-G14) -> 5607.8975 | I15: =H15*PI()/30*G15 -> 29.220097 | J15: =I15/($D$32*F15)*100 -> 80.763122 | K15: =G15*1000 -> 49.756861
C16: 無負荷時電流I0 | D16: 0.45 | E16: A(10V時) | F16: =F15+$D$16 -> 5.85 | G16: =F16*$D$29-$D$30 -> 0.054280212 | H16: =H15-$D$27*(G16-G15) -> 5539.07 | I16: =H16*PI()/30*G16 -> 31.48524 | J16: =I16/($D$32*F16)*100 -> 80.329736 | K16: =G16*1000 -> 54.280212
C17: 内部抵抗Rm | D17: 0.161 | E17: ohm | F17: =F16+$D$16 -> 6.3 | G17: =F17*$D$29-$D$30 -> 0.058803563 | H17: =H16-$D$27*(G17-G16) -> 5470.2425 | I17: =H17*PI()/30*G17 -> 33.685177 | J17: =I17/($D$32*F17)*100 -> 79.803785 | K17: =G17*1000 -> 58.803563
C18: 極数 | F18: =F17+$D$16 -> 6.75 | G18: =F18*$D$29-$D$30 -> 0.063326914 | H18: =H17-$D$27*(G18-G17) -> 5401.415 | I18: =H18*PI()/30*G18 -> 35.81991 | J18: =I18/($D$32*F18)*100 -> 79.203781 | K18: =G18*1000 -> 63.326914
C19: ターン数 | D19: 30 | F19: =F18+$D$16 -> 7.2 | G19: =F19*$D$29-$D$30 -> 0.067850265 | H19: =H18-$D$27*(G19-G18) -> 5332.5875 | I19: =H19*PI()/30*G19 -> 37.889437 | J19: =I19/($D$32*F19)*100 -> 78.54361 | K19: =G19*1000 -> 67.850265
C20: 最高回転数Npeak | E20: rpm | F20: =F19+$D$16 -> 7.65 | G20: =F20*$D$29-$D$30 -> 0.072373616 | H20: =H19-$D$27*(G20-G19) -> 5263.76 | I20: =H20*PI()/30*G20 -> 39.89376 | J20: =I20/($D$32*F20)*100 -> 77.833889 | K20: =G20*1000 -> 72.373616
C21: ESC タイミング | E21: deg | F21: =F20+$D$16 -> 8.1 | G21: =F21*$D$29-$D$30 -> 0.076896967 | H21: =H20-$D$27*(G21-G20) -> 5194.9325 | I21: =H21*PI()/30*G21 -> 41.832877 | J21: =I21/($D$32*F21)*100 -> 77.082877 | K21: =G21*1000 -> 76.896967
C22: ESC 周波数 | E22: kHz | F22: =F21+$D$16 -> 8.55 | G22: =F22*$D$29-$D$30 -> 0.081420318 | H22: =H21-$D$27*(G22-G21) -> 5126.105 | I22: =H22*PI()/30*G22 -> 43.70679 | J22: =I22/($D$32*F22)*100 -> 76.297093 | K22: =G22*1000 -> 81.420318
F23: =F22+$D$16 -> 9 | G23: =F23*$D$29-$D$30 -> 0.085943669 | H23: =H22-$D$27*(G23-G22) -> 5057.2775 | I23: =H23*PI()/30*G23 -> 45.515497 | J23: =I23/($D$32*F23)*100 -> 75.481754 | K23: =G23*1000 -> 85.943669
C24: I0測定時の電圧 | D24: 10 | E24: V | F24: =F23+$D$16 -> 9.45 | G24: =F24*$D$29-$D$30 -> 0.09046702 | H24: =H23-$D$27*(G24-G23) -> 4988.45 | I24: =H24*PI()/30*G24 -> 47.259 | J24: =I24/($D$32*F24)*100 -> 74.64108 | K24: =G24*1000 -> 90.46702
C25: 無負荷時回転数？ | D25: =D12*D24 -> 9500 | E25: rpm | F25: =F24+$D$16 -> 9.9 | G25: =F25*$D$29-$D$30 -> 0.094990371 | H25: =H24-$D$27*(G25-G24) -> 4919.6225 | I25: =H25*PI()/30*G25 -> 48.937297 | J25: =I25/($D$32*F25)*100 -> 73.778528 | K25: =G25*1000 -> 94.990371
D26: =D25*(PI()/30) -> 994.83767 | E26: rad/sec | F26: =F25+$D$16 -> 10.35 | G26: =F26*$D$29-$D$30 -> 0.099513722 | H26: =H25-$D$27*(G26-G25) -> 4850.795 | I26: =H26*PI()/30*G26 -> 50.55039 | J26: =I26/($D$32*F26)*100 -> 72.89695 | K26: =G26*1000 -> 99.513722
A27: maxon | C27: 回転数/トルク勾配 | D27: =(PI()/30)*((D17*D25^2)/(D24^2)) -> 15216.042 | E27: rpm/Nm | F27: =F26+$D$16 -> 10.8 | G27: =F27*$D$29-$D$30 -> 0.10403707 | H27: =H26-$D$27*(G27-G26) -> 4781.9675 | I27: =H27*PI()/30*G27 -> 52.098277 | J27: =I27/($D$32*F27)*100 -> 71.998725 | K27: =G27*1000 -> 104.03707
C28: 逆起電力定数Ke | D28: =D24/D26 -> 0.010051891 | E28: Vsec/rad | F28: =F27+$D$16 -> 11.25 | G28: =F28*$D$29-$D$30 -> 0.10856042 | H28: =H27-$D$27*(G28-G27) -> 4713.14 | I28: =H28*PI()/30*G28 -> 53.58096 | J28: =I28/($D$32*F28)*100 -> 71.085851 | K28: =G28*1000 -> 108.56042
C29: トルク定数Kt | D29: =D28 -> 0.010051891 | E29: Nm/A | F29: =F28+$D$16 -> 11.7 | G29: =F29*$D$29-$D$30 -> 0.11308378 | H29: =H28-$D$27*(G29-G28) -> 4644.3125 | I29: =H29*PI()/30*G29 -> 54.998437 | J29: =I29/($D$32*F29)*100 -> 70.160017 | K29: =G29*1000 -> 113.08378
C30: モータ内損失トルクTd | D30: =D29*D16 -> 0.004523351 | E30: Nm | F30: =F29+$D$16 -> 12.15 | G30: =F30*$D$29-$D$30 -> 0.11760713 | H30: =H29-$D$27*(G30-G29) -> 4575.485 | I30: =H30*PI()/30*G30 -> 56.35071 | J30: =I30/($D$32*F30)*100 -> 69.222664 | K30: =G30*1000 -> 117.60713
F31: =F30+$D$16 -> 12.6 | G31: =F31*$D$29-$D$30 -> 0.12213048 | H31: =H30-$D$27*(G31-G30) -> 4506.6575 | I31: =H31*PI()/30*G31 -> 57.637777 | J31: =I31/($D$32*F31)*100 -> 68.275027 | K31: =G31*1000 -> 122.13048
C32: 駆動電圧V | D32: =Graph!M2 -> 6.7 | E32: V | F32: =F31+$D$16 -> 13.05 | G32: =F32*$D$29-$D$30 -> 0.12665383 | H32: =H31-$D$27*(G32-G31) -> 4437.83 | I32: =H32*PI()/30*G32 -> 58.85964 | J32: =I32/($D$32*F32)*100 -> 67.318168 | K32: =G32*1000 -> 126.65383
C33: 理論最高回転数Nmax | D33: =D12*D32 -> 6365 | E33: rpm | F33: =F32+$D$16 -> 13.5 | G33: =F33*$D$29-$D$30 -> 0.13117718 | H33: =H32-$D$27*(G33-G32) -> 4369.0025 | I33: =H33*PI()/30*G33 -> 60.016297 | J33: =I33/($D$32*F33)*100 -> 66.35301 | K33: =G33*1000 -> 131.17718
C34: Nmax≦Npeak？ | D34: =D33/D20 -> #DIV/0! | F34: =F33+$D$16 -> 13.95 | G34: =F34*$D$29-$D$30 -> 0.13570053 | H34: =H33-$D$27*(G34-G33) -> 4300.175 | I34: =H34*PI()/30*G34 -> 61.10775 | J34: =I34/($D$32*F34)*100 -> 65.380356 | K34: =G34*1000 -> 135.70053
A35: maxon | C35: 起動電流IA | D35: =D32/D17 -> 41.614907 | E35: A | F35: =F34+$D$16 -> 14.4 | G35: =F35*$D$29-$D$30 -> 0.14022388 | H35: =H34-$D$27*(G35-G34) -> 4231.3475 | I35: =H35*PI()/30*G35 -> 62.133997 | J35: =I35/($D$32*F35)*100 -> 64.40091 | K35: =G35*1000 -> 140.22388
F36: =F35+$D$16 -> 14.85 | G36: =F36*$D$29-$D$30 -> 0.14474723 | H36: =H35-$D$27*(G36-G35) -> 4162.52 | I36: =H36*PI()/30*G36 -> 63.09504 | J36: =I36/($D$32*F36)*100 -> 63.415287 | K36: =G36*1000 -> 144.74723
C37: Rm/Kt^2 | D37: =D17/(D29^2) -> 1593.4202 | F37: =F36+$D$16 -> 15.3 | G37: =F37*$D$29-$D$30 -> 0.14927058 | H37: =H36-$D$27*(G37-G36) -> 4093.6925 | I37: =H37*PI()/30*G37 -> 63.990877 | J37: =I37/($D$32*F37)*100 -> 62.424034 | K37: =G37*1000 -> 149.27058
F38: =F37+$D$16 -> 15.75 | G38: =F38*$D$29-$D$30 -> 0.15379393 | H38: =H37-$D$27*(G38-G37) -> 4024.865 | I38: =H38*PI()/30*G38 -> 64.82151 | J38: =I38/($D$32*F38)*100 -> 61.427633 | K38: =G38*1000 -> 153.79393
F39: =F38+$D$16 -> 16.2 | G39: =F39*$D$29-$D$30 -> 0.15831729 | H39: =H38-$D$27*(G39-G38) -> 3956.0375 | I39: =H39*PI()/30*G39 -> 65.586937 | J39: =I39/($D$32*F39)*100 -> 60.426513 | K39: =G39*1000 -> 158.31729
C40: 最高効率時電流Iηmax | D40: =SQRT(D16*D32/D17) -> 4.3274367 | E40: A | F40: =F39+$D$16 -> 16.65 | G40: =F40*$D$29-$D$30 -> 0.16284064 | H40: =H39-$D$27*(G40-G39) -> 3887.21 | I40: =H40*PI()/30*G40 -> 66.28716 | J40: =I40/($D$32*F40)*100 -> 59.421057 | K40: =G40*1000 -> 162.84064
C41: nmax | D41: =((D40-D16)/D40)^2*100 -> 80.283812 | E41: % | F41: 17 | G41: =F41*$D$29-$D$30 -> 0.1663588 | H41: =H40-$D$27*(G41-G40) -> 3833.6775 | I41: =H41*PI()/30*G41 -> 66.786697 | J41: =I41/($D$32*F41)*100 -> 58.636258 | K41: =G41*1000 -> 166.3588
...

Sheet Z2213-24
C2: メーカー | D2: Hyperion | F2: 電流[A] | G2: 有効トルク[Nm] | H2: 回転数[rpm] | I2: 出力[W] | J2: 効率[%] | K2: 有効トルク[mNm]
C3: 品番 | D3: Z2213-24 | I3: =H3*PI()/30*G3 -> 0 | J3: =I3/($D$32*F3)*100 -> #DIV/0! | K3: =G3*1000 -> 0
C4: URL | F4: =D16 -> 0.6 | G4: =F4*$D$29-$D$30 -> 0 | H4: =D33 -> 5695 | I4: =H4*PI()/30*G4 -> 0 | J4: =I4/($D$32*F4)*100 -> 0 | K4: =G4*1000 -> 0
F5: =F4+$D$16 -> 1.2 | G5: =F5*$D$29-$D$30 -> 0.0067406799 | H5: =H4-$D$27*(G5-G4) -> 5626.15 | I5: =H5*PI()/30*G5 -> 3.9714 | J5: =I5/($D$32*F5)*100 -> 49.395522 | K5: =G5*1000 -> 6.7406799
B6: ハード | C6: 本体直径 | E6: mm | F6: =F5+$D$16 -> 1.8 | G6: =F6*$D$29-$D$30 -> 0.01348136 | H6: =H5-$D$27*(G6-G5) -> 5557.3 | I6: =H6*PI()/30*G6 -> 7.8456 | J6: =I6/($D$32*F6)*100 -> 65.054726 | K6: =G6*1000 -> 13.48136
C7: 本体長さ | E7: mm | F7: =F6+$D$16 -> 2.4 | G7: =F7*$D$29-$D$30 -> 0.02022204 | H7: =H6-$D$27*(G7-G6) -> 5488.45 | I7: =H7*PI()/30*G7 -> 11.6226 | J7: =I7/($D$32*F7)*100 -> 72.279851 | K7: =G7*1000 -> 20.22204
C8: シャフト径 | E8: mm | F8: =F7+$D$16 -> 3 | G8: =F8*$D$29-$D$30 -> 0.02696272 | H8: =H7-$D$27*(G8-G7) -> 5419.6 | I8: =H8*PI()/30*G8 -> 15.3024 | J8: =I8/($D$32*F8)*100 -> 76.131343 | K8: =G8*1000 -> 26.96272
C9: シャフト長 | E9: mm | F9: =F8+$D$16 -> 3.6 | G9: =F9*$D$29-$D$30 -> 0.0337034 | H9: =H8-$D$27*(G9-G8) -> 5350.75 | I9: =H9*PI()/30*G9 -> 18.885 | J9: =I9/($D$32*F9)*100 -> 78.29602 | K9: =G9*1000 -> 33.7034
C10: 重量 | D10: 53 | E10: g | F10: =F9+$D$16 -> 4.2 | G10: =F10*$D$29-$D$30 -> 0.04044408 | H10: =H9-$D$27*(G10-G9) -> 5281.9 | I10: =H10*PI()/30*G10 -> 22.3704 | J10: =I10/($D$32*F10)*100 -> 79.496802 | K10: =G10*1000 -> 40.44408
F11: =F10+$D$16 -> 4.8 | G11: =F11*$D$29-$D$30 -> 0.04718476 | H11: =H10-$D$27*(G11-G10) -> 5213.05 | I11: =H11*PI()/30*G11 -> 25.7586 | J11: =I11/($D$32*F11)*100 -> 80.095149 | K11: =G11*1000 -> 47.18476
B12: カタログスペック | C12: KV値 | D12: 850 | E12: rpm/V | F12: =F11+$D$16 -> 5.4 | G12: =F12*$D$29-$D$30 -> 0.05392544 | H12: =H11-$D$27*(G12-G11) -> 5144.2 | I12: =H12*PI()/30*G12 -> 29.0496 | J12: =I12/($D$32*F12)*100 -> 80.291874 | K12: =G12*1000 -> 53.92544
C13: 最大出力Pmax | E13: W | F13: =F12+$D$16 -> 6 | G13: =F13*$D$29-$D$30 -> 0.060666119 | H13: =H12-$D$27*(G13-G12) -> 5075.35 | I13: =H13*PI()/30*G13 -> 32.2434 | J13: =I13/($D$32*F13)*100 -> 80.207463 | K13: =G13*1000 -> 60.666119
C14: 最大電流Ipeak | D14: 16 | E14: A(10sec) | F14: =F13+$D$16 -> 6.6 | G14: =F14*$D$29-$D$30 -> 0.067406799 | H14: =H13-$D$27*(G14-G13) -> 5006.5 | I14: =H14*PI()/30*G14 -> 35.34 | J14: =I14/($D$32*F14)*100 -> 79.918589 | K14: =G14*1000 -> 67.406799
C15: 最高効率ηmax | E15: %(※) | F15: =F14+$D$16 -> 7.2 | G15: =F15*$D$29-$D$30 -> 0.074147479 | H15: =H14-$D$27*(G15-G14) -> 4937.65 | I15: =H15*PI()/30*G15 -> 38.3394 | J15: =I15/($D$32*F15)*100 -> 79.476368 | K15: =G15*1000 -> 74.147479
C16: 無負荷時電流I0 | D16: 0.6 | E16: A(10V時) | F16: =F15+$D$16 -> 7.8 | G16: =F16*$D$29-$D$30 -> 0.080888159 | H16: =H15-$D$27*(G16-G15) -> 4868.8 | I16: =H16*PI()/30*G16 -> 41.2416 | J16: =I16/($D$32*F16)*100 -> 78.916188 | K16: =G16*1000 -> 80.888159
C17: 内部抵抗Rm | D17: 0.135 | E17: ohm | F17: =F16+$D$16 -> 8.4 | G17: =F17*$D$29-$D$30 -> 0.087628839 | H17: =H16-$D$27*(G17-G16) -> 4799.95 | I17: =H17*PI()/30*G17 -> 44.0466 | J17: =I17/($D$32*F17)*100 -> 78.263326 | K17: =G17*1000 -> 87.628839
C18: 極数 | F18: =F17+$D$16 -> 9 | G18: =F18*$D$29-$D$30 -> 0.094369519 | H18: =H17-$D$27*(G18-G17) -> 4731.1 | I18: =H18*PI()/30*G18 -> 46.7544 | J18: =I18/($D$32*F18)*100 -> 77.536318 | K18: =G18*1000 -> 94.369519
C19: ターン数 | D19: 24 | F19: =F18+$D$16 -> 9.6 | G19: =F19*$D$29-$D$30 -> 0.1011102 | H19: =H18-$D$27*(G19-G18) -> 4662.25 | I19: =H19*PI()/30*G19 -> 49.365 | J19: =I19/($D$32*F19)*100 -> 76.749067 | K19: =G19*1000 -> 101.1102
C20: 最高回転数Npeak | E20: rpm | F20: =F19+$D$16 -> 10.2 | G20: =F20*$D$29-$D$30 -> 0.10785088 | H20: =H19-$D$27*(G20-G19) -> 4593.4 | I20: =H20*PI()/30*G20 -> 51.8784 | J20: =I20/($D$32*F20)*100 -> 75.912204 | K20: =G20*1000 -> 107.85088
C21: ESC タイミング | E21: deg | F21: =F20+$D$16 -> 10.8 | G21: =F21*$D$29-$D$30 -> 0.11459156 | H21: =H20-$D$27*(G21-G20) -> 4524.55 | I21: =H21*PI()/30*G21 -> 54.2946 | J21: =I21/($D$32*F21)*100 -> 75.033997 | K21: =G21*1000 -> 114.59156
C22: ESC 周波数 | E22: kHz | F22: =F21+$D$16 -> 11.4 | G22: =F22*$D$29-$D$30 -> 0.12133224 | H22: =H21-$D$27*(G22-G21) -> 4455.7 | I22: =H22*PI()/30*G22 -> 56.6136 | J22: =I22/($D$32*F22)*100 -> 74.120974 | K22: =G22*1000 -> 121.33224
F23: =F22+$D$16 -> 12 | G23: =F23*$D$29-$D$30 -> 0.12807292 | H23: =H22-$D$27*(G23-G22) -> 4386.85 | I23: =H23*PI()/30*G23 -> 58.8354 | J23: =I23/($D$32*F23)*100 -> 73.178358 | K23: =G23*1000 -> 128.07292
C24: I0測定時の電圧 | D24: 10 | E24: V | F24: =F23+$D$16 -> 12.6 | G24: =F24*$D$29-$D$30 -> 0.1348136 | H24: =H23-$D$27*(G24-G23) -> 4318 | I24: =H24*PI()/30*G24 -> 60.96 | J24: =I24/($D$32*F24)*100 -> 72.210377 | K24: =G24*1000 -> 134.8136
C25: 無負荷時回転数？ | D25: =D12*D24 -> 8500 | E25: rpm | F25: =F24+$D$16 -> 13.2 | G25: =F25*$D$29-$D$30 -> 0.14155428 | H25: =H24-$D$27*(G25-G24) -> 4249.15 | I25: =H25*PI()/30*G25 -> 62.9874 | J25: =I25/($D$32*F25)*100 -> 71.220488 | K25: =G25*1000 -> 141.55428
D26: =D25*(PI()/30) -> 890.11792 | E26: rad/sec | F26: =F25+$D$16 -> 13.8 | G26: =F26*$D$29-$D$30 -> 0.14829496 | H26: =H25-$D$27*(G26-G25) -> 4180.3 | I26: =H26*PI()/30*G26 -> 64.9176 | J26: =I26/($D$32*F26)*100 -> 70.211551 | K26: =G26*1000 -> 148.29496
A27: maxon | C27: 回転数/トルク勾配 | D27: =(PI()/30)*((D17*D25^2)/(D24^2)) -> 10214.103 | E27: rpm/Nm | F27: =F26+$D$16 -> 14.4 | G27: =F27*$D$29-$D$30 -> 0.15503564 | H27: =H26-$D$27*(G27-G26) -> 4111.45 | I27: =H27*PI()/30*G27 -> 66.7506 | J27: =I27/($D$32*F27)*100 -> 69.185945 | K27: =G27*1000 -> 155.03564
C28: 逆起電力定数Ke | D28: =D24/D26 -> 0.011234467 | E28: Vsec/rad | F28: =F27+$D$16 -> 15 | G28: =F28*$D$29-$D$30 -> 0.16177632 | H28: =H27-$D$27*(G28-G27) -> 4042.6 | I28: =H28*PI()/30*G28 -> 68.4864 | J28: =I28/($D$32*F28)*100 -> 68.145672 | K28: =G28*1000 -> 161.77632
C29: トルク定数Kt | D29: =D28 -> 0.011234467 | E29: Nm/A | F29: =F28+$D$16 -> 15.6 | G29: =F29*$D$29-$D$30 -> 0.168517 | H29: =H28-$D$27*(G29-G28) -> 3973.75 | I29: =H29*PI()/30*G29 -> 70.125 | J29: =I29/($D$32*F29)*100 -> 67.092423 | K29: =G29*1000 -> 168.517
C30: モータ内損失トルクTd | D30: =D29*D16 -> 0.0067406799 | E30: Nm | F30: 16 | G30: =F30*$D$29-$D$30 -> 0.17301079 | H30: =H29-$D$27*(G30-G29) -> 3927.85 | I30: =H30*PI()/30*G30 -> 71.1634 | J30: =I30/($D$32*F30)*100 -> 66.383769 | K30: =G30*1000 -> 173.01079
C32: 駆動電圧V | D32: =Graph!M2 -> 6.7 | E32: V
C33: 理論最高回転数Nmax | D33: =D12*D32 -> 5695 | E33: rpm
C34: Nmax≦Npeak？ | D34: =D33/D20 -> #DIV/0!
A35: maxon | C35: 起動電流IA | D35: =D32/D17 -> 49.62963 | E35: A
C37: Rm/Kt^2 | D37: =D17/(D29^2) -> 1069.6184
C40: 最高効率時電流Iηmax | D40: =SQRT(D16*D32/D17) -> 5.4569018 | E40: A
C41: nmax | D41: =((D40-D16)/D40)^2*100 -> 79.218455 | E41: %
C42: I | D42: =D40 -> 5.4569018 | E42: A
C43: Pout | D43: =(D42-D16)*(D32-D42*D17) -> 28.963251 | E43: W

Sheet Z2209-32
C2: メーカー | D2: Hyperion | F2: 電流[A] | G2: 有効トルク[Nm] | H2: 回転数[rpm] | I2: 出力[W] | J2: 効率[%] | K2: 有効トルク[mNm]
C3: 品番 | D3: Z2209-32 | I3: =H3*PI()/30*G3 -> 0 | J3: =I3/($D$32*F3)*100 -> #DIV/0! | K3: =G3*1000 -> 0
C4: URL | F4: =D16 -> 0.55 | G4: =F4*$D$29-$D$30 -> 0 | H4: =D33 -> 6097 | I4: =H4*PI()/30*G4 -> 0 | J4: =I4/($D$32*F4)*100 -> 0 | K4: =G4*1000 -> 0
F5: =F4+$D$16 -> 1.1 | G5: =F5*$D$29-$D$30 -> 0.0057715529 | H5: =H4-$D$27*(G5-G4) -> 6006.91 | I5: =H5*PI()/30*G5 -> 3.63055 | J5: =I5/($D$32*F5)*100 -> 49.261194 | K5: =G5*1000 -> 5.7715529
B6: ハード | C6: 本体直径 | E6: mm | F6: =F5+$D$16 -> 1.65 | G6: =F6*$D$29-$D$30 -> 0.011543106 | H6: =H5-$D$27*(G6-G5) -> 5916.82 | I6: =H6*PI()/30*G6 -> 7.1522 | J6: =I6/($D$32*F6)*100 -> 64.696517 | K6: =G6*1000 -> 11.543106
C7: 本体長さ | E7: mm | F7: =F6+$D$16 -> 2.2 | G7: =F7*$D$29-$D$30 -> 0.017314659 | H7: =H6-$D$27*(G7-G6) -> 5826.73 | I7: =H7*PI()/30*G7 -> 10.56495 | J7: =I7/($D$32*F7)*100 -> 71.675373 | K7: =G7*1000 -> 17.314659
C8: シャフト径 | E8: mm | F8: =F7+$D$16 -> 2.75 | G8: =F8*$D$29-$D$30 -> 0.023086212 | H8: =H7-$D$27*(G8-G7) -> 5736.64 | I8: =H8*PI()/30*G8 -> 13.8688 | J8: =I8/($D$32*F8)*100 -> 75.271642 | K8: =G8*1000 -> 23.086212
C9: シャフト長 | E9: mm | F9: =F8+$D$16 -> 3.3 | G9: =F9*$D$29-$D$30 -> 0.028857764 | H9: =H8-$D$27*(G9-G8) -> 5646.55 | I9: =H9*PI()/30*G9 -> 17.06375 | J9: =I9/($D$32*F9)*100 -> 77.176617 | K9: =G9*1000 -> 28.857764
C10: 重量 | E10: g | F10: =F9+$D$16 -> 3.85 | G10: =F10*$D$29-$D$30 -> 0.034629317 | H10: =H9-$D$27*(G10-G9) -> 5556.46 | I10: =H10*PI()/30*G10 -> 20.1498 | J10: =I10/($D$32*F10)*100 -> 78.115139 | K10: =G10*1000 -> 34.629317
F11: =F10+$D$16 -> 4.4 | G11: =F11*$D$29-$D$30 -> 0.04040087 | H11: =H10-$D$27*(G11-G10) -> 5466.37 | I11: =H11*PI()/30*G11 -> 23.12695 | J11: =I11/($D$32*F11)*100 -> 78.449627 | K11: =G11*1000 -> 40.40087
B12: カタログスペック | C12: KV値 | D12: 910 | E12: rpm/V | F12: =F11+$D$16 -> 4.95 | G12: =F12*$D$29-$D$30 -> 0.046172423 | H12: =H11-$D$27*(G12-G11) -> 5376.28 | I12: =H12*PI()/30*G12 -> 25.9952 | J12: =I12/($D$32*F12)*100 -> 78.381426 | K12: =G12*1000 -> 46.172423
C13: 最大出力Pmax | E13: W | F13: =F12+$D$16 -> 5.5 | G13: =F13*$D$29-$D$30 -> 0.051943976 | H13: =H12-$D$27*(G13-G12) -> 5286.19 | I13: =H13*PI()/30*G13 -> 28.75455 | J13: =I13/($D$32*F13)*100 -> 78.031343 | K13: =G13*1000 -> 51.943976
C14: 最大電流Ipeak | D14: 12 | E14: A(10sec) | F14: =F13+$D$16 -> 6.05 | G14: =F14*$D$29-$D$30 -> 0.057715529 | H14: =H13-$D$27*(G14-G13) -> 5196.1 | I14: =H14*PI()/30*G14 -> 31.405 | J14: =I14/($D$32*F14)*100 -> 77.476255 | K14: =G14*1000 -> 57.715529
C15: 最高効率ηmax | E15: %(※) | F15: =F14+$D$16 -> 6.6 | G15: =F15*$D$29-$D$30 -> 0.063487082 | H15: =H14-$D$27*(G15-G14) -> 5106.01 | I15: =H15*PI()/30*G15 -> 33.94655 | J15: =I15/($D$32*F15)*100 -> 76.767413 | K15: =G15*1000 -> 63.487082
C16: 無負荷時電流I0 | D16: 0.55 | E16: A(10V時) | F16: =F15+$D$16 -> 7.15 | G16: =F16*$D$29-$D$30 -> 0.069258635 | H16: =H15-$D$27*(G16-G15) -> 5015.92 | I16: =H16*PI()/30*G16 -> 36.3792 | J16: =I16/($D$32*F16)*100 -> 75.940299 | K16: =G16*1000 -> 69.258635
C17: 内部抵抗Rm | D17: 0.18 | E17: ohm | F17: =F16+$D$16 -> 7.7 | G17: =F17*$D$29-$D$30 -> 0.075030187 | H17: =H16-$D$27*(G17-G16) -> 4925.83 | I17: =H17*PI()/30*G17 -> 38.70295 | J17: =I17/($D$32*F17)*100 -> 75.020256 | K17: =G17*1000 -> 75.030187
C18: 極数 | F18: =F17+$D$16 -> 8.25 | G18: =F18*$D$29-$D$30 -> 0.08080174 | H18: =H17-$D$27*(G18-G17) -> 4835.74 | I18: =H18*PI()/30*G18 -> 40.9178 | J18: =I18/($D$32*F18)*100 -> 74.025871 | K18: =G18*1000 -> 80.80174
C19: ターン数 | D19: 32 | F19: =F18+$D$16 -> 8.8 | G19: =F19*$D$29-$D$30 -> 0.086573293 | H19: =H18-$D$27*(G19-G18) -> 4745.65 | I19: =H19*PI()/30*G19 -> 43.02375 | J19: =I19/($D$32*F19)*100 -> 72.971082 | K19: =G19*1000 -> 86.573293
C20: 最高回転数Npeak | E20: rpm | F20: =F19+$D$16 -> 9.35 | G20: =F20*$D$29-$D$30 -> 0.092344846 | H20: =H19-$D$27*(G20-G19) -> 4655.56 | I20: =H20*PI()/30*G20 -> 45.0208 | J20: =I20/($D$32*F20)*100 -> 71.86655 | K20: =G20*1000 -> 92.344846
C21: ESC タイミング | E21: deg | F21: =F20+$D$16 -> 9.9 | G21: =F21*$D$29-$D$30 -> 0.098116399 | H21: =H20-$D$27*(G21-G20) -> 4565.47 | I21: =H21*PI()/30*G21 -> 46.90895 | J21: =I21/($D$32*F21)*100 -> 70.720564 | K21: =G21*1000 -> 98.116399
C22: ESC 周波数 | E22: kHz | F22: =F21+$D$16 -> 10.45 | G22: =F22*$D$29-$D$30 -> 0.10388795 | H22: =H21-$D$27*(G22-G21) -> 4475.38 | I22: =H22*PI()/30*G22 -> 48.6882 | J22: =I22/($D$32*F22)*100 -> 69.53967 | K22: =G22*1000 -> 103.88795
F23: =F22+$D$16 -> 11 | G23: =F23*$D$29-$D$30 -> 0.1096595 | H23: =H22-$D$27*(G23-G22) -> 4385.29 | I23: =H23*PI()/30*G23 -> 50.35855 | J23: =I23/($D$32*F23)*100 -> 68.329104 | K23: =G23*1000 -> 109.6595
C24: I0測定時の電圧 | D24: 10 | E24: V | F24: =F23+$D$16 -> 11.55 | G24: =F24*$D$29-$D$30 -> 0.11543106 | H24: =H23-$D$27*(G24-G23) -> 4295.2 | I24: =H24*PI()/30*G24 -> 51.92 | J24: =I24/($D$32*F24)*100 -> 67.093106 | K24: =G24*1000 -> 115.43106
C25: 無負荷時回転数？ | D25: =D12*D24 -> 9100 | E25: rpm | F25: 12 | G25: =F25*$D$29-$D$30 -> 0.12015324 | H25: =H24-$D$27*(G25-G24) -> 4221.49 | I25: =H25*PI()/30*G25 -> 53.11655 | J25: =I25/($D$32*F25)*100 -> 66.065361 | K25: =G25*1000 -> 120.15324
D26: =D25*(PI()/30) -> 952.94977 | E26: rad/sec
A27: maxon | C27: 回転数/トルク勾配 | D27: =(PI()/30)*((D17*D25^2)/(D24^2)) -> 15609.317 | E27: rpm/Nm
C28: 逆起電力定数Ke | D28: =D24/D26 -> 0.010493733 | E28: Vsec/rad
C29: トルク定数Kt | D29: =D28 -> 0.010493733 | E29: Nm/A
C30: モータ内損失トルクTd | D30: =D29*D16 -> 0.0057715529 | E30: Nm
C32: 駆動電圧V | D32: =Graph!M2 -> 6.7 | E32: V
C33: 理論最高回転数Nmax | D33: =D12*D32 -> 6097 | E33: rpm
C34: Nmax≦Npeak？ | D34: =D33/D20 -> #DIV/0!
A35: maxon | C35: 起動電流IA | D35: =D32/D17 -> 37.222222 | E35: A
C37: Rm/Kt^2 | D37: =D17/(D29^2) -> 1634.6039
C40: 最高効率時電流Iηmax | D40: =SQRT(D16*D32/D17) -> 4.524624 | E40: A
C41: nmax | D41: =((D40-D16)/D40)^2*100 -> 77.166199 | E41: %
C42: I | D42: =D40 -> 4.524624 | E42: A
C43: Pout | D43: =(D42-D16)*(D32-D42*D17) -> 23.392918 | E43: W

Sheet Graph
L2: 印加電圧 | M2: 6.7 | N2: V
O22: 163 | P22: Hz
O23: =O22*60 -> 9780
O24: =O23/2 -> 4890 | P24: rpm

Sheet Sheet8
C3: Amp | D3: 重量 | F3: BEC | G3: PC | H3: Brake | I3: Bat.Type | J3: Cut.Mode | K3: Cut.Vol | L3: Soft Start | M3: 過電流保護 | N3: 周波数 | O3: 進角 | P3: rot. | Q3: Throtle/Gov | R3: 価格
A4: SkyRC | B4: Swift 20A ESC | C4: 20 | D4: 19 | E4: 34*23*12 | F4: 5V 2A | G4: No | H4: On/Off | I4: Yes | J4: - | K4: 3/cell？ | L4: - | M4: - | N4: - | O4: - | P4: Yes | Q4: - | R4: 2000
A5: Hyperion | B5: HP-ATLAS-025LB | C5: 25 | D5: 27.3 | E5: 51*26.1*8.8 | F5: 5V 3A | G5: No | H5: VS/S/H/VH/なし | I5: - | J5: 50%/LED/なし | K5: 5-13.8 0.2V | L5: ある？ | M5: On/Off | N5: 8kHz | O5: Auto/5-30 5° | P5: - | Q5: Yes/Fix | R5: 3000
A6: Hyperion | B6: HP-TITAN-20PW31 | C6: 20 | D6: 21 | E6: 38*24*7.5 | F6: 5V 1.5A | G6: Yes | H6: On/Off | I6: Yes | J6: S/H/なし | K6: 2-3.2/cell 0.1V | L6: On/Off | M6: - | N6: 8/16kHz | O6: Auto/7/22-30 | P6: Yes | Q6: L/M/H/Fix | R6: 5800
A7: Waypoint | B7: W-EBLESC-15 | C7: 15 | D7: 17 | F7: 5V 2A
A8: Waypoint | B8: W-EBLESC-25 | C8: 25 | D8: 21 | F8: 5V 2A
A9: Turnigy(HOBBYWING OEM) | B9: PLUSH-18 | C9: 18 | D9: 19 | E9: 45*24*11 | F9: 5V 2A | G9: No | H9: On/Off | I9: Yes | J9: S/H | K9: 2.6/2.85/3.1/cell | L9: VS/S/N | M9: - | N9: - | O9: L/M/H | P9: - | Q9: Fix? | R9: 1760
A10: Turnigy(HOBBYWING OEM) | B10: PLUSH-25 | C10: 25 | D10: 22 | E10: 45*24*11 | F10: 5V 2A | G10: No | H10: On/Off | I10: Yes | J10: S/H | K10: 2.6/2.85/3.1/cell | L10: VS/S/N | M10: - | N10: - | O10: L/M/H | P10: - | Q10: Fix? | R10: 1890
A11: HOBBYWING | B11: FLYFUN-18A | C11: 18 | D11: 19 | E11: 45*24*11 | F11: 5V 2A | G11: No | H11: On/Off | I11: Yes | J11: S/H | K11: 2.85/3.15/3.3/cell | L11: VS/S/N | M11: - | N11: - | O11: 3.75/15/26.25 | P11: - | Q11: Fix? | R11: 1580 | S11: 980 | T11: =R11*2+S11 -> 4140
A12: Hacker | B12: X-20-Pro | C12: 20 | D12: 16 | E12: 42*24*9 | F12: 2-4Servo | G12: Yes | H12: On/Off | I12: Yes | J12: S/H | K12: 3.2/cell or 5.8 | L12: - | M12: - | N12: 8/16kHz | O12: Auto/7/22-30 | P12: Yes | Q12: L/M/H/Fix | R12: 5700 | S12: 2200 | T12: =R12*2+S12 -> 13600
A13: Hacker | B13: X-20 | C13: 20 | D13: 16 | E13: 42*24*9 | F13: 2-5Servo | R13: 5240
A14: Castle Creations | B14: Phoenix-25 | C14: 25 | D14: 17 | E14: 27.4x23.1x4.1 | F14: ? | G14: Yes | H14: SHDelay有無/なし | I14: - | J14: S/H | K14: 3.2/cell or 6 | L14: VS/S/F | M14: 4段階/なし | N14: 12/16/24/Out | O14: L/M/H | P14: Yes | Q14: Auto/Fix/L/H | R14: 7200
B15: Thunderbird-18 | G15: Yes | H15: On/Off | I15: Yes | J15: - | K15: 3/cell 変更可 | L15: - | M15: - | N15: - | O15: - | P15: Yes | Q15: Fix? | R15: 4980
B16: FutureU11.20e | C16: 20 | D16: 20 | E16: 41x26x9 | R16: 15593
B19: ZS2213-22 | D19: 59.7 | F19: =D19-18 -> 41.7
B20: A20-22LEVO | D20: 55 | F20: =D20-18 -> 37
D21: 45.4 | F21: =D21-18 -> 27.4
C24: 21 | D24: 2 | E24: =C24*D24 -> 42
C25: 41.7 | D25: 2 | E25: =C25*D25 -> 83.4
C26: 109 | D26: 1 | E26: =C26*D26 -> 109
E28: =SUM(E24:E26) -> 234.4
E29: 685
E30: -80
E31: =SUM(E28:E30) -> 839.4
E32: =E31*1.2 -> 1007.28
B34: モータ毎消費電流 | C34: 9.3 | D34: A
B35: 合計消費電流 | C35: =C34*2 -> 18.6 | D35: A
B38: 目標飛行時間 | C38: 10 | D38: min
B39: 必要容量 | C39: =C38/60*C35*1000 -> 3100 | D39: mAh
B40: ７掛け | C40: =C39/0.7 -> 4428.5714 | D40: mAh
B42: 搭載容量 | C42: 2000 | D42: mAh
B43: 飛行可能時間 | C43: =C42/1000/C35*60 -> 6.4516129 | D43: min
B44: ７掛け | C44: =C43*0.7 -> 4.516129

Sheet Sheet4
